Workbook

Sheet calculator
A1: ROH_INT | C1: {=OFFSET(INDIRECT($A$137&"!$C$1:$AX$1"),0,$X$1,1,20)} | W1: SIANG | X1: =IF(W1="PAGI",14,IF(W1="SIANG",28,IF(W1="MALAM2",28,0))) | Y1: stiffness Mw/Hz | Z1: 1800 | AA1: 0.07 | AB1: =Z1*AA1 | AC1: =AB1*2 | AD1: =50.08 | AE1: 0.16 | AI1: SAGULING | AK1: CIRATA | AM1: JATILUHUR | AO1: MRICA
A2: Load Sistem | C2: {=OFFSET(INDIRECT($A$137&"!$C$1:$AX$1"),MATCH("Pembangkitan Total",INDIRECT($A$137&"!$A$1:$A$300"),0)-1,$X$1,1,20)} | AA2: 50 | AB2: =AA2/Z1 | AD2: 50 | AE2: =AD2-AB2 | AF2: =AD2+AB2 | AH2: MAX | AI2: 643 | AK2: 220 | AM2: 107 | AO2: 231
A3: Trend Naik/Turun | D3: =D2-C2 | E3: =E2-D2 | F3: =F2-E2 | G3: =G2-F2 | H3: =H2-G2 | I3: =I2-H2 | J3: =J2-I2 | K3: =K2-J2 | ... V3: =V2-U2 | AH3: Basah | AI3: 636.2 | AK3: 213 | AM3: 98.3 | AO3: Target | AP3: 227.65
A4: SCH Contribute | D4: =D68-C68 | E4: =E68-D68 | F4: =F68-E68 | G4: =G68-F68 | H4: =H68-G68 | I4: =I68-H68 | J4: =J68-I68 | K4: =K68-J68 | ... V4: =V68-U68 | AH4: Normal | AI4: 632.9 | AK4: 210.4 | AM4: 94.9 | AO4: Now | AP4: 230.26
A5: Additional | D5: =SUM(D7:D67) | E5: =SUM(E7:E67) | F5: =SUM(F7:F67) | G5: =SUM(G7:G67) | H5: =SUM(H7:H67) | I5: =SUM(I7:I67) | J5: =SUM(J7:J67) | K5: =SUM(K7:K67) | ... V5: =SUM(V7:V67) | AH5: Kering | AI5: 627.3 | AK5: 207 | AM5: 90.3 | AO5: Inflow | AP5: 82
X6: real | Y6: roh | Z6: int | AA6: PR | AH6: Stop Unit | AI6: 625 | AK6: 206 | AM6: 87.5
A7: PLTU ADPLA #1 | B7: FALSE | X7: =(IFERROR(AVERAGEIF(INDEX(RT!$D$1:$AY$812,MATCH("PLTU ADIPALA #1",RT!$A$1:$A$812,0),0),"<>0"),0))/615 | Y7: {=SUMPRODUCT(VALUE(INDEX(ROH!$C$1:$AX$300,MATCH("PLTU ADIPALA #1",ROH!$A$1:$A$300,0),0)))/48/615} | Z7: {=(SUMPRODUCT(VALUE(INDEX(INT!$C$1:$AX$300,MATCH("PLTU ADIPALA #1",INT!$A$1:$A$300,0),0)))/48)/615} | AH7: MIN | AI7: 623 | AK7: 206.07 | AM7: 75 | AO7: 226
A8: PLTU CLCAP #4 | B8: FALSE | X8: =(IFERROR(AVERAGEIF(INDEX(RT!$D$1:$AY$812,MATCH("PLTU CLCAP #4",RT!$A$1:$A$812,0),0),"<>0"),0))/945 | Y8: {=(SUMPRODUCT(VALUE(INDEX(ROH!$C$1:$AX$300,MATCH("PLTU CLCAP #4",ROH!$A$1:$A$300,0),0)))/48)/945} | Z8: {=(SUMPRODUCT(VALUE(INDEX(INT!$C$1:$AX$300,MATCH("PLTU CLCAP #4",INT!$A$1:$A$300,0),0)))/48)/945} | AB8: RR | AC8: menit
A9: PLTU TJATI #3 | B9: TRUE | X9: =(IFERROR(AVERAGEIF(INDEX(RT!$D$1:$AY$812,MATCH("PLTU TJATI #3",RT!$A$1:$A$812,0),0),"<>0"),0)+IFERROR(AVERAGEIF(INDEX(RT!$D$1:$AY$812,MATCH("PLTU TJATI #4",RT!$A$1:$A$812,0),0),"<>0"),0))/(660.8*2) | Y9: {=(SUMPRODUCT(VALUE(INDEX(ROH!$C$1:$AX$300,MATCH("PLTU TJATI #3",ROH!$A$1:$A$300,0),0)))/48+SUMPRODUCT(VALUE(INDEX(ROH!$C$1:$AX$300,MATCH("PLTU TJATI #4",ROH!$A$1:$A$300,0),0)))/48)/(660.8*2)} | Z9: {=(SUMPRODUCT(VALUE(INDEX(INT!$C$1:$AX$300,MATCH("PLTU TJATI #3",INT!$A$1:$A$300,0),0)))/48+SUMPRODUCT(VALUE(INDEX(INT!$C$1:$AX$300,MATCH("PLTU TJATI #4",INT!$A$1:$A$300,0),0)))/48)/(660.8*2)} | AB9: 10 | AC9: 30 | AD9: =AB9*AC9 | AF9: MT | AG9: 1.1
A10: PLTU TJATI #4 | B10: TRUE | AG10: 1.2
A11: PLTU LBE #1 | B11: TRUE | X11: =(IFERROR(AVERAGEIF(INDEX(RT!$D$1:$AY$812,MATCH("PLTU LBE #1",RT!$A$1:$A$812,0),0),"<>0"),0))/625 | Y11: {=(SUMPRODUCT(VALUE(INDEX(ROH!$C$1:$AX$300,MATCH("PLTU LBE #1",ROH!$A$1:$A$300,0),0)))/48)/625} | Z11: {=(SUMPRODUCT(VALUE(INDEX(INT!$C$1:$AX$300,MATCH("PLTU LBE #1",INT!$A$1:$A$300,0),0)))/48)/625} | AG11: 1.3
A12: PLTU TJATIBJP #5 | B12: FALSE | X12: =(IFERROR(AVERAGEIF(INDEX(RT!$D$1:$AY$812,MATCH("PLTU TJATIBJP #5",RT!$A$1:$A$812,0),0),"<>0"),0)+IFERROR(AVERAGEIF(INDEX(RT!$D$1:$AY$812,MATCH("PLTU TJATIBJP #6",RT!$A$1:$A$812,0),0),"<>0"),0))/(1000*2) | Y12: {=(SUMPRODUCT(VALUE(INDEX(ROH!$C$1:$AX$300,MATCH("PLTU TJATIBJP #5",ROH!$A$1:$A$300,0),0)))/48+SUMPRODUCT(VALUE(INDEX(ROH!$C$1:$AX$300,MATCH("PLTU TJATIBJP #6",ROH!$A$1:$A$300,0),0)))/48)/(1000*2)} | Z12: {=(SUMPRODUCT(VALUE(INDEX(INT!$C$1:$AX$300,MATCH("PLTU TJATIBJP #5",INT!$A$1:$A$300,0),0)))/48+SUMPRODUCT(VALUE(INDEX(INT!$C$1:$AX$300,MATCH("PLTU TJATIBJP #6",INT!$A$1:$A$300,0),0)))/48)/(1000*2)} | AG12: 1.0
A13: PLTU TJATIBJP #6 | B13: FALSE | AG13: 2.1 | AH13: operasi | AI13: combine | AJ13: 135 | AK13: STOP
A14: PLTU BATANG #1 | B14: FALSE | X14: =(IFERROR(AVERAGEIF(INDEX(RT!$D$1:$AY$812,MATCH("PLTU BATANG #1",RT!$A$1:$A$812,0),0),"<>0"),0)+IFERROR(AVERAGEIF(INDEX(RT!$D$1:$AY$812,MATCH("PLTU BATANG #2",RT!$A$1:$A$812,0),0),"<>0"),0))/(950*2) | Y14: {=(SUMPRODUCT(VALUE(INDEX(ROH!$C$1:$AX$300,MATCH("PLTU BATANG #1",ROH!$A$1:$A$300,0),0)))/48+SUMPRODUCT(VALUE(INDEX(ROH!$C$1:$AX$300,MATCH("PLTU BATANG #2",ROH!$A$1:$A$300,0),0)))/48)/(950*2)} | Z14: {=(SUMPRODUCT(VALUE(INDEX(INT!$C$1:$AX$300,MATCH("PLTU BATANG #1",INT!$A$1:$A$300,0),0)))/48+SUMPRODUCT(VALUE(INDEX(INT!$C$1:$AX$300,MATCH("PLTU BATANG #2",INT!$A$1:$A$300,0),0)))/48)/(950*2)} | AG14: 2.2 | AH14: operasi | AI14: combine | AJ14: 135
A15: PLTU BATANG #2 | B15: FALSE | AC15: 14.1 | AD15: 4.34 | AE15: 440 | AG15: 2.0
A16: PLTU JAWA #09 | B16: FALSE | G16: 100 | X16: =(IFERROR(AVERAGEIF(INDEX(RT!$D$1:$AY$812,MATCH("PLTU JAWA #09",RT!$A$1:$A$812,0),0),"<>0"),0)+IFERROR(AVERAGEIF(INDEX(RT!$D$1:$AY$812,MATCH("PLTU JAWA #10",RT!$A$1:$A$812,0),0),"<>0"),0))/(1000*2) | Y16: {=(SUMPRODUCT(VALUE(INDEX(ROH!$C$1:$AX$300,MATCH("PLTU JAWA #09",ROH!$A$1:$A$300,0),0)))/48+SUMPRODUCT(VALUE(INDEX(ROH!$C$1:$AX$300,MATCH("PLTU JAWA #10",ROH!$A$1:$A$300,0),0)))/48)/(1000*2)} | Z16: {=(SUMPRODUCT(VALUE(INDEX(INT!$C$1:$AX$300,MATCH("PLTU JAWA #09",INT!$A$1:$A$300,0),0)))/48+SUMPRODUCT(VALUE(INDEX(INT!$C$1:$AX$300,MATCH("PLTU JAWA #10",INT!$A$1:$A$300,0),0)))/48)/(1000*2)} | AC16: gas | AD16: sikron gas | AE16: co hsd | AG16: 3.1
A17: PLTU JAWA #10 | B17: FALSE | G17: 100 | AA17: 30 | AB17: 3 jam | AG17: 3.2
A18: PLTU TJ AWAR2 #1 | B18: FALSE | X18: =(IFERROR(AVERAGEIF(INDEX(RT!$D$1:$AY$812,MATCH("PLTU TJ AWAR2 #1",RT!$A$1:$A$812,0),0),"<>0"),0)+IFERROR(AVERAGEIF(INDEX(RT!$D$1:$AY$812,MATCH("PLTU TJ AWAR2 #2",RT!$A$1:$A$812,0),0),"<>0"),0))/(323*2) | Y18: {=(SUMPRODUCT(VALUE(INDEX(ROH!$C$1:$AX$300,MATCH("PLTU TJ AWAR2 #1",ROH!$A$1:$A$300,0),0)))/48+SUMPRODUCT(VALUE(INDEX(ROH!$C$1:$AX$300,MATCH("PLTU TJ AWAR2 #2",ROH!$A$1:$A$300,0),0)))/48)/(323*2)} | Z18: {=(SUMPRODUCT(VALUE(INDEX(INT!$C$1:$AX$300,MATCH("PLTU TJ AWAR2 #1",INT!$A$1:$A$300,0),0)))/48+SUMPRODUCT(VALUE(INDEX(INT!$C$1:$AX$300,MATCH("PLTU TJ AWAR2 #2",INT!$A$1:$A$300,0),0)))/48)/(323*2)} | AA18: 30 | AB18: 2jam | AG18: 3.3 | AH18: operasi | AI18: hsd | AJ18: 135 | AK18: STOP
A19: PLTU TJ AWAR2 #2 | B19: FALSE | AA19: 30 | AG19: 3.0
A20: PLTU TJATI #1 | B20: FALSE | X20: =(IFERROR(AVERAGEIF(INDEX(RT!$D$1:$AY$812,MATCH("PLTU TJATI #1",RT!$A$1:$A$812,0),0),"<>0"),0)+IFERROR(AVERAGEIF(INDEX(RT!$D$1:$AY$812,MATCH("PLTU TJATI #2",RT!$A$1:$A$812,0),0),"<>0"),0))/(660.8*2) | Y20: {=(SUMPRODUCT(VALUE(INDEX(ROH!$C$1:$AX$300,MATCH("PLTU TJATI #1",ROH!$A$1:$A$300,0),0)))/48+SUMPRODUCT(VALUE(INDEX(ROH!$C$1:$AX$300,MATCH("PLTU TJATI #2",ROH!$A$1:$A$300,0),0)))/48)/(660.8*2)} | Z20: {=(SUMPRODUCT(VALUE(INDEX(INT!$C$1:$AX$300,MATCH("PLTU TJATI #1",INT!$A$1:$A$300,0),0)))/48+SUMPRODUCT(VALUE(INDEX(INT!$C$1:$AX$300,MATCH("PLTU TJATI #2",INT!$A$1:$A$300,0),0)))/48)/(660.8*2)} | AG20: 4.1 | AH20: operasi | AI20: combine | AJ20: 100 | AK20: STOP
A21: PLTU TJATI #2 | B21: FALSE | AG21: 4.2 | AH21: operasi | AI21: combine | AJ21: 100
A22: PLTU PITON #1 | B22: FALSE | G22: -300 | X22: =(IFERROR(AVERAGEIF(INDEX(RT!$D$1:$AY$812,MATCH("PLTU PITON #1",RT!$A$1:$A$812,0),0),"<>0"),0)+IFERROR(AVERAGEIF(INDEX(RT!$D$1:$AY$812,MATCH("PLTU PITON #2",RT!$A$1:$A$812,0),0),"<>0"),0))/(370*2) | Y22: {=(SUMPRODUCT(VALUE(INDEX(ROH!$C$1:$AX$300,MATCH("PLTU PITON #1",ROH!$A$1:$A$300,0),0)))/48+SUMPRODUCT(VALUE(INDEX(ROH!$C$1:$AX$300,MATCH("PLTU PITON #2",ROH!$A$1:$A$300,0),0)))/48)/(370*2)} | Z22: {=(SUMPRODUCT(VALUE(INDEX(INT!$C$1:$AX$300,MATCH("PLTU PITON #1",INT!$A$1:$A$300,0),0)))/48+SUMPRODUCT(VALUE(INDEX(INT!$C$1:$AX$300,MATCH("PLTU PITON #2",INT!$A$1:$A$300,0),0)))/48)/(370*2)} | AG22: 4.3 | AH22: operasi | AI22: combine | AJ22: 100 | AM22: variasi musim | AN22: DMN-DMP-POMO-FODER-RS
A23: PLTU PITON #2 | B23: FALSE | AG23: 4.0
A24: PLTU Jawa Power #5 | B24: TRUE | G24: 200 | X24: =(IFERROR(AVERAGEIF(INDEX(RT!$D$1:$AY$812,MATCH("PLTU Jawa Power #5",RT!$A$1:$A$812,0),0),"<>0"),0)+IFERROR(AVERAGEIF(INDEX(RT!$D$1:$AY$812,MATCH("PLTU Jawa Power #6",RT!$A$1:$A$812,0),0),"<>0"),0))/(610*2) | Y24: {=(SUMPRODUCT(VALUE(INDEX(ROH!$C$1:$AX$300,MATCH("PLTU Jawa Power #5",ROH!$A$1:$A$300,0),0)))/48+SUMPRODUCT(VALUE(INDEX(ROH!$C$1:$AX$300,MATCH("PLTU Jawa Power #6",ROH!$A$1:$A$300,0),0)))/48)/(610*2)} | Z24: {=(SUMPRODUCT(VALUE(INDEX(INT!$C$1:$AX$300,MATCH("PLTU Jawa Power #5",INT!$A$1:$A$300,0),0)))/48+SUMPRODUCT(VALUE(INDEX(INT!$C$1:$AX$300,MATCH("PLTU Jawa Power #6",INT!$A$1:$A$300,0),0)))/48)/(610*2)} | AG24: 5.1
A25: PLTU Jawa Power #6 | B25: TRUE | G25: 200 | AG25: 5.0
A26: PLTU PEC #3 | B26: TRUE | X26: =(IFERROR(AVERAGEIF(INDEX(RT!$D$1:$AY$812,MATCH("PLTU PEC #3",RT!$A$1:$A$812,0),0),"<>0"),0))/811 | Y26: {=(SUMPRODUCT(VALUE(INDEX(ROH!$C$1:$AX$300,MATCH("PLTU PEC #3",ROH!$A$1:$A$300,0),0)))/48)/811} | Z26: {=(SUMPRODUCT(VALUE(INDEX(INT!$C$1:$AX$300,MATCH("PLTU PEC #3",INT!$A$1:$A$300,0),0)))/48)/811} | AF26: TL | AG26: 1.1 | AH26: operasi | AI26: BBM | AJ26: 80
A27: PLTU CLCAP #3 | B27: TRUE | AG27: 2.1 | AH27: operasi | AI27: BBM | AJ27: 80
A28: PLTU JAWA 7 #1 | B28: FALSE | X28: =(IFERROR(AVERAGEIF(INDEX(RT!$D$1:$AY$812,MATCH("PLTU JAWA 7 #1",RT!$A$1:$A$812,0),0),"<>0"),0)+IFERROR(AVERAGEIF(INDEX(RT!$D$1:$AY$812,MATCH("PLTU JAWA 7 #2",RT!$A$1:$A$812,0),0),"<>0"),0))/(991*2) | Y28: {=(SUMPRODUCT(VALUE(INDEX(ROH!$C$1:$AX$300,MATCH("PLTU JAWA 7 #1",ROH!$A$1:$A$300,0),0)))/48+SUMPRODUCT(VALUE(INDEX(ROH!$C$1:$AX$300,MATCH("PLTU JAWA 7 #2",ROH!$A$1:$A$300,0),0)))/48)/(991*2)} | Z28: {=(SUMPRODUCT(VALUE(INDEX(INT!$C$1:$AX$300,MATCH("PLTU JAWA 7 #1",INT!$A$1:$A$300,0),0)))/48+SUMPRODUCT(VALUE(INDEX(INT!$C$1:$AX$300,MATCH("PLTU JAWA 7 #2",INT!$A$1:$A$300,0),0)))/48)/(991*2)} | AF28: GRS | AG28: 1.1 | AH28: operasi | AI28: BBM | AJ28: 80
A29: PLTU JAWA 7 #2 | B29: FALSE | AG29: 2.1 | AH29: operasi | AI29: BBM | AJ29: 80
A30: PLTU PAITON #9 | B30: TRUE | X30: =(IFERROR(AVERAGEIF(INDEX(RT!$D$1:$AY$812,MATCH("PLTU PAITON #9",RT!$A$1:$A$812,0),0),"<>0"),0))/615 | Y30: {=(SUMPRODUCT(VALUE(INDEX(ROH!$C$1:$AX$300,MATCH("PLTU PAITON #9",ROH!$A$1:$A$300,0),0)))/48)/615} | Z30: {=(SUMPRODUCT(VALUE(INDEX(INT!$C$1:$AX$300,MATCH("PLTU PAITON #9",INT!$A$1:$A$300,0),0)))/48)/615} | AF30: GRT | AG30: 1.2
A31: Suralaya 5-7 | B31: FALSE | AG31: 2.1
A32: PLTU PACITAN #1 | B32: FALSE | X32: =(IFERROR(AVERAGEIF(INDEX(RT!$D$1:$AY$812,MATCH("PLTU PACITAN #1",RT!$A$1:$A$812,0),0),"<>0"),0)+IFERROR(AVERAGEIF(INDEX(RT!$D$1:$AY$812,MATCH("PLTU PACITAN #2",RT!$A$1:$A$812,0),0),"<>0"),0))/(280*2) | Y32: {=(SUMPRODUCT(VALUE(INDEX(ROH!$C$1:$AX$300,MATCH("PLTU PACITAN #1",ROH!$A$1:$A$300,0),0)))/48+SUMPRODUCT(VALUE(INDEX(ROH!$C$1:$AX$300,MATCH("PLTU PACITAN #2",ROH!$A$1:$A$300,0),0)))/48)/(280*2)} | Z32: {=(SUMPRODUCT(VALUE(INDEX(INT!$C$1:$AX$300,MATCH("PLTU PACITAN #1",INT!$A$1:$A$300,0),0)))/48+SUMPRODUCT(VALUE(INDEX(INT!$C$1:$AX$300,MATCH("PLTU PACITAN #2",INT!$A$1:$A$300,0),0)))/48)/(280*2)} | AG32: 2.2
A33: PLTU PACITAN #2 | B33: FALSE
A34: PLTU CEPR #1 | B34: FALSE | X34: =(IFERROR(AVERAGEIF(INDEX(RT!$D$1:$AY$812,MATCH("PLTU CEPR #1",RT!$A$1:$A$812,0),0),"<>0"),0))/924 | Y34: {=(SUMPRODUCT(VALUE(INDEX(ROH!$C$1:$AX$300,MATCH("PLTU CEPR #1",ROH!$A$1:$A$300,0),0)))/48)/924} | Z34: {=(SUMPRODUCT(VALUE(INDEX(INT!$C$1:$AX$300,MATCH("PLTU CEPR #1",INT!$A$1:$A$300,0),0)))/48)/924}
A35: PLTU IPP CIREBON #1 | B35: TRUE | X35: =(IFERROR(AVERAGEIF(INDEX(RT!$D$1:$AY$812,MATCH("PLTU IPP CIREBON #1",RT!$A$1:$A$812,0),0),"<>0"),0))/660 | Y35: {=(SUMPRODUCT(VALUE(INDEX(ROH!$C$1:$AX$300,MATCH("PLTU IPP CIREBON #1",ROH!$A$1:$A$300,0),0)))/48)/660} | Z35: {=(SUMPRODUCT(VALUE(INDEX(INT!$C$1:$AX$300,MATCH("PLTU IPP CIREBON #1",INT!$A$1:$A$300,0),0)))/48)/660}
A36: Celukan Bawang | B36: FALSE
A37: PLTU PEC #7 | B37: TRUE | X37: =(IFERROR(AVERAGEIF(INDEX(RT!$D$1:$AY$812,MATCH("PLTU PEC #7",RT!$A$1:$A$812,0),0),"<>0"),0)+IFERROR(AVERAGEIF(INDEX(RT!$D$1:$AY$812,MATCH("PLTU PEC #8",RT!$A$1:$A$812,0),0),"<>0"),0))/(610*2) | Y37: {=(SUMPRODUCT(VALUE(INDEX(ROH!$C$1:$AX$300,MATCH("PLTU PEC #7",ROH!$A$1:$A$300,0),0)))/48+SUMPRODUCT(VALUE(INDEX(ROH!$C$1:$AX$300,MATCH("PLTU PEC #8",ROH!$A$1:$A$300,0),0)))/48)/(610*2)} | Z37: {=(SUMPRODUCT(VALUE(INDEX(INT!$C$1:$AX$300,MATCH("PLTU PEC #7",INT!$A$1:$A$300,0),0)))/48+SUMPRODUCT(VALUE(INDEX(INT!$C$1:$AX$300,MATCH("PLTU PEC #8",INT!$A$1:$A$300,0),0)))/48)/(610*2)}
A38: PLTU PEC #8 | B38: TRUE | AC38: mvar cirata jangan lebih 150 sekunder, batang kediri, suralaya sebisa mungkin dibawah 511
A39: PLTU PRATU #1 | B39: FALSE | X39: =(IFERROR(AVERAGEIF(INDEX(RT!$D$1:$AY$812,MATCH("PLTU PRATU #1",RT!$A$1:$A$812,0),0),"<>0"),0)+IFERROR(AVERAGEIF(INDEX(RT!$D$1:$AY$812,MATCH("PLTU PRATU #2",RT!$A$1:$A$812,0),0),"<>0"),0)+IFERROR(AVERAGEIF(INDEX(RT!$D$1:$AY$812,MATCH("PLTU PRATU #3",RT!$A$1:$A$812,0),0),"<>0"),0))/(323*3) | Y39: {=(SUMPRODUCT(VALUE(INDEX(ROH!$C$1:$AX$300,MATCH("PLTU PRATU #1",ROH!$A$1:$A$300,0),0)))/48+SUMPRODUCT(VALUE(INDEX(ROH!$C$1:$AX$300,MATCH("PLTU PRATU #2",ROH!$A$1:$A$300,0),0)))/48+SUMPRODUCT(VALUE(INDEX(ROH!$C$1:$AX$300,MATCH("PLTU PRATU #3",ROH!$A$1:$A$300,0),0)))/48)/(323*3)} | Z39: {=(SUMPRODUCT(VALUE(INDEX(INT!$C$1:$AX$300,MATCH("PLTU PRATU #1",INT!$A$1:$A$300,0),0)))/48+SUMPRODUCT(VALUE(INDEX(INT!$C$1:$AX$300,MATCH("PLTU PRATU #2",INT!$A$1:$A$300,0),0)))/48+SUMPRODUCT(VALUE(INDEX(INT!$C$1:$AX$300,MATCH("PLTU PRATU #3",INT!$A$1:$A$300,0),0)))/48)/(323*3)}
A40: PLTU PRATU #2 | B40: FALSE
...

Sheet monitor
B1: JAWA7 | D1: JAWA910
A2: 0.020833333 | B2: 416
A3: 0.041666667 | B3: 417 | J3: 1.3 mkarang gagal sinkrong
A4: 0.0625 | B4: 417
A5: 0.083333333 | B5: 415
A6: 0.10416667 | B6: 415
A7: 0.125 | B7: 414
A8: 0.14583333 | B8: 415
A9: 0.16666667 | B9: 414
A10: 0.1875 | B10: 415
A11: 0.20833333 | B11: 418
A12: 0.22916667 | B12: 416
A13: 0.25 | B13: 415
A14: 0.27083333 | B14: 418
A15: 0.29166667 | B15: 418
... A49: 1 | B49: 416

Sheet INT
A1: LOKASI | B1: DMN | C1: 00.30 | D1: 01.00 | E1: 01.30 | F1: 02.00 | G1: 02.30 | H1: 03.00 | I1: 03.30 | J1: 04.00 | K1: 04.30 | L1: 05.00 | M1: 05.30 | N1: 06.00 | O1: 06.30 | P1: 07.00 | Q1: 07.30 | R1: 08.00 | S1: 08.30 | T1: 09.00 | U1: 09.30 | V1: 10.00 | W1: 10.30 | X1: 11.00 | Y1: 11.30 | Z1: 12.00 | AA1: 12.30 | AB1: 13.00 | AC1: 13.30 | AD1: 14.00 | AE1: 14.30 | AF1: 15.00 | AG1: 15.30 | AH1: 16.00 | AI1: 16.30 | AJ1: 17.00 | AK1: 17.30 | AL1: 18.00 | AM1: 18.30 | AN1: 19.00 | AO1: 19.30 | AP1: 20.00 | AQ1: 20.30 | AR1: 21.00 | AS1: 21.30 | AT1: 22.00 | AU1: 22.30 | AV1: 23.00 | AW1: 23.30 | AX1: 24.00
A3: RJKB
C4: PT. INDONESIA POWER | D4: PT. INDONESIA POWER | E4: PT. INDONESIA POWER | F4: PT. INDONESIA POWER | G4: PT. INDONESIA POWER | H4: PT. INDONESIA POWER | I4: PT. INDONESIA POWER | J4: PT. INDONESIA POWER | K4: PT. INDONESIA POWER | L4: PT. INDONESIA POWER | M4: PT. INDONESIA POWER | N4: PT. INDONESIA POWER | O4: PT. INDONESIA POWER | P4: PT. INDONESIA POWER | Q4: PT. INDONESIA POWER | R4: PT. INDONESIA POWER | S4: PT. INDONESIA POWER | T4: PT. INDONESIA POWER | U4: PT. INDONESIA POWER | V4: PT. INDONESIA POWER | W4: PT. INDONESIA POWER | X4: PT. INDONESIA POWER | Y4: PT. INDONESIA POWER | Z4: PT. INDONESIA POWER | AA4: PT. INDONESIA POWER | AB4: PT. INDONESIA POWER | AC4: PT. INDONESIA POWER | AD4: PT. INDONESIA POWER | AE4: PT. INDONESIA POWER | AF4: PT. INDONESIA POWER | AG4: PT. INDONESIA POWER | AH4: PT. INDONESIA POWER | AI4: PT. INDONESIA POWER | AJ4: PT. INDONESIA POWER | AK4: PT. INDONESIA POWER | AL4: PT. INDONESIA POWER | AM4: PT. INDONESIA POWER | AN4: PT. INDONESIA POWER | AO4: PT. INDONESIA POWER | AP4: PT. INDONESIA POWER | AQ4: PT. INDONESIA POWER | AR4: PT. INDONESIA POWER | AS4: PT. INDONESIA POWER | AT4: PT. INDONESIA POWER | AU4: PT. INDONESIA POWER | AV4: PT. INDONESIA POWER | AW4: PT. INDONESIA POWER | AX4: PT. INDONESIA POWER
A6: PLTA Region 1 | C6: 4 | D6: 3 | E6: 3 | F6: 3 | G6: 3 | H6: 3 | I6: 3 | J6: 3 | K6: 3 | L6: 3 | M6: 3 | N6: 3 | O6: 4 | P6: 4 | Q6: 4 | R6: 4 | S6: 4 | T6: 4 | U6: 4 | V6: 4 | W6: 8 | X6: 8 | Y6: 8 | Z6: 8 | AA6: 8 | AB6: 8 | AC6: 8 | AD6: 8 | AE6: 8 | AF6: 8 | AG6: 8 | AH6: 8 | AI6: 8 | AJ6: 8 | AK6: 8 | AL6: 8 | AM6: 8 | AN6: 8 | AO6: 8 | AP6: 4 | AQ6: 4 | AR6: 4 | AS6: 4 | AT6: 4 | AU6: 4 | AV6: 4 | AW6: 4 | AX6: 4
A8: PLTU SRLYA #1 | B8: 371.5 | C8: 284.2 | D8: 284.2 | E8: 284.2 | F8: 284.2 | G8: 284.2 | H8: 284.2 | I8: 284.2 | J8: 284.2 | K8: 284.2 | L8: 284.2 | M8: 284.2 | N8: 284.2 | O8: 284.2 | P8: 200 | Q8: 200 | R8: 216.8 | S8: 216.8 | T8: 333.2 | U8: 333.2 | V8: 333.2 | W8: 333.2 | X8: 333.2 | Y8: 333.2 | Z8: 333.2 | AA8: 333.2 | AB8: 333.2 | AC8: 333.2 | AD8: 333.2 | AE8: 333.2 | AF8: 333.2 | AG8: 333.2 | AH8: 333.2 | AI8: 333.2 | AJ8: 333.2 | AK8: 333.2 | AL8: 333.2 | AM8: 333.2 | AN8: 333.2 | AO8: 333.2 | AP8: 333.2 | AQ8: 333.2 | AR8: 333.2 | AS8: 200 | AT8: 333.2 | AU8: 333.2 | AV8: 333.2 | AW8: 333.2 | AX8: 333.2
A9: PLTU SRLYA #2 | B9: 371.5 | C9: 284.2 | D9: 284.2 | E9: 284.2 | F9: 284.2 | G9: 284.2 | H9: 284.2 | I9: 284.2 | J9: 284.2 | K9: 284.2 | L9: 284.2 | M9: 284.2 | N9: 284.2 | O9: 284.2 | P9: 248 | Q9: 230 | R9: 230 | S9: 230 | T9: 333.2 | U9: 333.2 | V9: 333.2 | W9: 333.2 | X9: 333.2 | Y9: 333.2 | Z9: 333.2 | AA9: 333.2 | AB9: 333.2 | AC9: 333.2 | AD9: 333.2 | AE9: 333.2 | AF9: 333.2 | AG9: 333.2 | AH9: 333.2 | AI9: 333.2 | AJ9: 333.2 | AK9: 333.2 | AL9: 333.2 | AM9: 333.2 | AN9: 333.2 | AO9: 333.2 | AP9: 333.2 | AQ9: 333.2 | AR9: 333.2 | AS9: 246.8 | AT9: 333.2 | AU9: 333.2 | AV9: 333.2 | AW9: 333.2 | AX9: 333.2
A10: PLTU SRLYA #4 | B10: 371.5 | C10: 284.2 | D10: 284.2 | E10: 284.2 | F10: 284.2 | G10: 284.2 | H10: 284.2 | I10: 284.2 | J10: 284.2 | K10: 284.2 | L10: 284.2 | M10: 284.2 | N10: 284.2 | O10: 284.2 | P10: 200 | Q10: 200 | R10: 333.2 | S10: 333.2 | T10: 333.2 | U10: 333.2 | V10: 333.2 | W10: 333.2 | X10: 333.2 | Y10: 333.2 | Z10: 333.2 | AA10: 333.2 | AB10: 333.2 | AC10: 333.2 | AD10: 333.2 | AE10: 333.2 | AF10: 333.2 | AG10: 333.2 | AH10: 333.2 | AI10: 333.2 | AJ10: 333.2 | AK10: 333.2 | AL10: 333.2 | AM10: 333.2 | AN10: 333.2 | AO10: 333.2 | AP10: 333.2 | AQ10: 333.2 | AR10: 333.2 | AS10: 333.2 | AT10: 333.2 | AU10: 333.2 | AV10: 333.2 | AW10: 333.2 | AX10: 333.2
A11: PLTU SRLYA #5 | B11: 575.2 | C11: 320 | D11: 320 | E11: 320 | F11: 320 | G11: 320 | H11: 318 | I11: 318 | J11: 318 | K11: 318 | L11: 318 | M11: 318 | N11: 318 | O11: 318 | P11: 300 | Q11: 310 | R11: 400 | S11: 400 | T11: 490 | U11: 490 | V11: 490 | W11: 490 | X11: 490 | Y11: 490 | Z11: 490 | AA11: 490 | AB11: 490 | AC11: 490 | AD11: 490 | AE11: 490 | AF11: 490 | AG11: 490 | AH11: 490 | AI11: 490 | AJ11: 490 | AK11: 490 | AL11: 490 | AM11: 490 | AN11: 490 | AO11: 490 | AP11: 490 | AQ11: 490 | AR11: 490 | AS11: 400 | AT11: 310 | AU11: 310 | AV11: 310 | AW11: 310 | AX11: 310
A12: PLTU SRLYA #6 | B12: 575.2 | C12: 357.4 | D12: 357.4 | E12: 357.4 | F12: 357.4 | G12: 357.4 | H12: 357.4 | I12: 357.4 | J12: 357.4 | K12: 357.4 | L12: 357.4 | M12: 357.4 | N12: 357.4 | O12: 357.4 | P12: 490 | Q12: 490 | R12: 340 | S12: 340 | T12: 490 | U12: 490 | V12: 490 | W12: 490 | X12: 490 | Y12: 490 | Z12: 490 | AA12: 490 | AB12: 490 | AC12: 490 | AD12: 490 | AE12: 490 | AF12: 490 | AG12: 490 | AH12: 490 | AI12: 490 | AJ12: 490 | AK12: 490 | AL12: 490 | AM12: 490 | AN12: 490 | AO12: 490 | AP12: 490 | AQ12: 490 | AR12: 490 | AS12: 340 | AT12: 300.4 | AU12: 300.4 | AV12: 300.4 | AW12: 300.4 | AX12: 300.4
A13: PLTU SRLYA #7 | B13: 575.2 | C13: 390 | D13: 390 | E13: 390 | F13: 390 | G13: 390 | H13: 392 | I13: 392 | J13: 392 | K13: 392 | L13: 392 | M13: 392 | N13: 392 | O13: 392 | P13: 482 | Q13: 490 | R13: 400 | S13: 400 | T13: 490 | U13: 490 | V13: 490 | W13: 490 | X13: 490 | Y13: 490 | Z13: 490 | AA13: 490 | AB13: 490 | AC13: 490 | AD13: 490 | AE13: 490 | AF13: 490 | AG13: 490 | AH13: 490 | AI13: 490 | AJ13: 490 | AK13: 490 | AL13: 490 | AM13: 490 | AN13: 490 | AO13: 490 | AP13: 490 | AQ13: 490 | AR13: 490 | AS13: 400 | AT13: 310 | AU13: 310 | AV13: 310 | AW13: 310 | AX13: 310
A15: PLTGU PRIOK #1 | C15: 150.38 | D15: 149.21 | E15: 149.21 | F15: 149.21 | G15: 149.21 | H15: 149.21 | I15: 149.21 | J15: 149.21 | K15: 149.21 | L15: 149.21 | M15: 145.43 | N15: 178.05 | O15: 204.4 | P15: 547.5 | Q15: 547.5 | R15: 547.5 | S15: 547.5 | T15: 354.78 | U15: 354.78 | V15: 354.78 | W15: 354.78 | X15: 354.78 | Y15: 354.78 | Z15: 354.78 | AA15: 354.78 | AB15: 374.4 | AC15: 381.06 | AD15: 381.06 | AE15: 381.06 | AF15: 381.06 | AG15: 381.06 | AH15: 354.78 | AI15: 354.78 | AJ15: 354.78 | AK15: 354.78 | AL15: 441.02 | AM15: 386.9 | AN15: 354.78 | AO15: 354.78 | AP15: 354.78 | AQ15: 354.78 | AR15: 354.78 | AS15: 354.78 | AT15: 354.78 | AU15: 252.58 | AV15: 252.58 | AW15: 252.52 | AX15: 204.4
A16: PLTGU PRIOK #2 | C16: 122.2 | D16: 111.09 | E16: 111.09 | F16: 111.09 | G16: 111.09 | H16: 111.09 | I16: 111.09 | J16: 111.09 | K16: 111.09 | L16: 111.09 | M16: 111.09 | N16: 111.09 | O16: 126.72 | P16: 157.97 | Q16: 204.4 | R16: 204.4 | S16: 204.4 | T16: 252.58 | U16: 252.58 | V16: 252.58 | W16: 252.58 | X16: 252.58 | Y16: 252.58 | Z16: 252.58 | AA16: 252.58 | AB16: 252.58 | AC16: 278.86 | AD16: 278.86 | AE16: 278.86 | AF16: 278.86 | AG16: 278.86 | AH16: 252.58 | AI16: 252.58 | AJ16: 252.58 | AK16: 252.58 | AL16: 287.15 | AM16: 284.7 | AN16: 252.58 | AO16: 252.58 | AP16: 252.58 | AQ16: 252.58 | AR16: 252.58 | AS16: 252.58 | AT16: 252.58 | AU16: 252.58 | AV16: 230.62 | AW16: 248.29 | AX16: 247.31
A17: PLTGU PRIOK #3 | C17: 539.23 | D17: 539.23 | E17: 539.23 | F17: 539.23 | G17: 539.23 | H17: 539.23 | I17: 539.23 | J17: 539.23 | K17: 528.47 | L17: 539.23 | M17: 539.23 | N17: 522.87 | O17: 526.17 | P17: 444.26 | Q17: 539.23 | R17: 539.23 | S17: 539.23 | T17: 692.52 | U17: 719.1 | V17: 665.66 | W17: 695.95 | X17: 715.63 | Y17: 703.91 | Z17: 692.52 | AA17: 674.52 | AB17: 710.9 | AC17: 720 | AD17: 720 | AE17: 720 | AF17: 720 | AG17: 720 | AH17: 716.68 | AI17: 683.55 | AJ17: 650.98 | AK17: 615.19 | AL17: 720 | AM17: 720 | AN17: 626.55 | AO17: 626.55 | AP17: 626.55 | AQ17: 626.55 | AR17: 611.8 | AS17: 713.87 | AT17: 573.2 | AU17: 629.8 | AV17: 539.23 | AW17: 539.23 | AX17: 539.23
A18: PLTGU PRIOK #4 | C18: 0 | D18: 0 | E18: 0 | F18: 0 | G18: 0 | H18: 0 | I18: 0 | J18: 0 | K18: 0 | L18: 0 | M18: 0 | N18: 0 | O18: 0 | P18: 0 | Q18: 0 | R18: 0 | S18: 0 | T18: 0 | U18: 53.74 | V18: 150 | W18: 150 | X18: 150 | Y18: 150 | Z18: 150 | AA18: 150 | AB18: 150 | AC18: 163.78 | AD18: 171.1 | AE18: 177.99 | AF18: 178.82 | AG18: 167.59 | AH18: 150 | AI18: 150 | AJ18: 150 | AK18: 150 | AL18: 283.25 | AM18: 221 | AN18: 150 | AO18: 150 | AP18: 150 | AQ18: 75 | AR18: 25 | AS18: 0 | AT18: 0 | AU18: 0 | AV18: 0 | AW18: 0 | AX18: 0
A20: PLTP SALAK #1 | B20: 56.5 | C20: 56.5 | D20: 56.5 | E20: 56.5 | F20: 56.5 | G20: 56.5 | H20: 56.5 | I20: 56.5 | J20: 56.5 | K20: 56.5 | L20: 56.5 | M20: 56.5 | N20: 56.5 | O20: 56.5 | P20: 56.5 | Q20: 46.5 | R20: 46.5 | S20: 56.5 | T20: 56.5 | U20: 56.5 | V20: 56.5 | W20: 56.5 | X20: 56.5 | Y20: 56.5 | Z20: 56.5 | AA20: 56.5 | AB20: 56.5 | AC20: 56.5 | AD20: 56.5 | AE20: 56.5 | AF20: 56.5 | AG20: 56.5 | AH20: 56.5 | AI20: 56.5 | AJ20: 56.5 | AK20: 56.5 | AL20: 56.5 | AM20: 56.5 | AN20: 56.5 | AO20: 56.5 | AP20: 56.5 | AQ20: 56.5 | AR20: 56.5 | AS20: 56.5 | AT20: 56.5 | AU20: 56.5 | AV20: 56.5 | AW20: 56.5 | AX20: 56.5
A21: PLTP SALAK #2 | B21: 56.5 | C21: 56.5 | D21: 56.5 | E21: 56.5 | F21: 56.5 | G21: 56.5 | H21: 56.5 | I21: 56.5 | J21: 56.5 | K21: 56.5 | L21: 56.5 | M21: 56.5 | N21: 56.5 | O21: 56.5 | P21: 56.5 | Q21: 46.5 | R21: 46.5 | S21: 56.5 | T21: 56.5 | U21: 56.5 | V21: 56.5 | W21: 56.5 | X21: 56.5 | Y21: 56.5 | Z21: 56.5 | AA21: 56.5 | AB21: 56.5 | AC21: 56.5 | AD21: 56.5 | AE21: 56.5 | AF21: 56.5 | AG21: 56.5 | AH21: 56.5 | AI21: 56.5 | AJ21: 56.5 | AK21: 56.5 | AL21: 56.5 | AM21: 56.5 | AN21: 56.5 | AO21: 56.5 | AP21: 56.5 | AQ21: 56.5 | AR21: 56.5 | AS21: 56.5 | AT21: 56.5 | AU21: 56.5 | AV21: 56.5 | AW21: 56.5 | AX21: 56.5
A22: PLTP SALAK #3 | B22: 57 | C22: 57 | D22: 57 | E22: 57 | F22: 57 | G22: 57 | H22: 57 | I22: 57 | J22: 57 | K22: 57 | L22: 57 | M22: 57 | N22: 57 | O22: 57 | P22: 57 | Q22: 47 | R22: 47 | S22: 57 | T22: 57 | U22: 57 | V22: 57 | W22: 57 | X22: 57 | Y22: 57 | Z22: 57 | AA22: 57 | AB22: 57 | AC22: 57 | AD22: 57 | AE22: 57 | AF22: 57 | AG22: 57 | AH22: 57 | AI22: 57 | AJ22: 57 | AK22: 57 | AL22: 57 | AM22: 57 | AN22: 57 | AO22: 57 | AP22: 57 | AQ22: 57 | AR22: 57 | AS22: 57 | AT22: 57 | AU22: 57 | AV22: 57 | AW22: 57 | AX22: 57
A24: PLTD SNYAN #1 | B24: 17.02 | C24: 0 | D24: 0 | E24: 0 | F24: 0 | G24: 0 | H24: 0 | I24: 0 | J24: 0 | K24: 0 | L24: 0 | M24: 0 | N24: 0 | O24: 0 | P24: 0 | Q24: 0 | R24: 0 | S24: 0 | T24: 0 | U24: 0 | V24: 0 | W24: 0 | X24: 0 | Y24: 0 | Z24: 0 | AA24: 0 | AB24: 0 | AC24: 0 | AD24: 0 | AE24: 0 | AF24: 0 | AG24: 0 | AH24: 0 | AI24: 0 | AJ24: 0 | AK24: 0 | AL24: 0 | AM24: 0 | AN24: 0 | AO24: 0 | AP24: 0 | AQ24: 0 | AR24: 0 | AS24: 0 | AT24: 0 | AU24: 0 | AV24: 0 | AW24: 0 | AX24: 0
A25: PLTD SNYAN #2 | B25: 17.02 | C25: 0 | D25: 0 | E25: 0 | F25: 0 | G25: 0 | H25: 0 | I25: 0 | J25: 0 | K25: 0 | L25: 0 | M25: 0 | N25: 0 | O25: 0 | P25: 0 | Q25: 0 | R25: 0 | S25: 0 | T25: 0 | U25: 0 | V25: 0 | W25: 0 | X25: 0 | Y25: 0 | Z25: 0 | AA25: 0 | AB25: 0 | AC25: 0 | AD25: 0 | AE25: 0 | AF25: 0 | AG25: 0 | AH25: 0 | AI25: 0 | AJ25: 0 | AK25: 0 | AL25: 0 | AM25: 0 | AN25: 0 | AO25: 0 | AP25: 0 | AQ25: 0 | AR25: 0 | AS25: 0 | AT25: 0 | AU25: 0 | AV25: 0 | AW25: 0 | AX25: 0
A26: PLTD SNYAN #3 | B26: 17.02 | C26: 0 | D26: 0 | E26: 0 | F26: 0 | G26: 0 | H26: 0 | I26: 0 | J26: 0 | K26: 0 | L26: 0 | M26: 0 | N26: 0 | O26: 0 | P26: 0 | Q26: 0 | R26: 0 | S26: 0 | T26: 0 | U26: 0 | V26: 0 | W26: 0 | X26: 0 | Y26: 0 | Z26: 0 | AA26: 0 | AB26: 0 | AC26: 0 | AD26: 0 | AE26: 0 | AF26: 0 | AG26: 0 | AH26: 0 | AI26: 0 | AJ26: 0 | AK26: 0 | AL26: 0 | AM26: 0 | AN26: 0 | AO26: 0 | AP26: 0 | AQ26: 0 | AR26: 0 | AS26: 0 | AT26: 0 | AU26: 0 | AV26: 0 | AW26: 0 | AX26: 0
A27: PLTD SNYAN #4 | B27: 17.02 | C27: 0 | D27: 0 | E27: 0 | F27: 0 | G27: 0 | H27: 0 | I27: 0 | J27: 0 | K27: 0 | L27: 0 | M27: 0 | N27: 0 | O27: 0 | P27: 0 | Q27: 0 | R27: 0 | S27: 0 | T27: 0 | U27: 0 | V27: 0 | W27: 0 | X27: 0 | Y27: 0 | Z27: 0 | AA27: 0 | AB27: 0 | AC27: 0 | AD27: 0 | AE27: 0 | AF27: 0 | AG27: 0 | AH27: 0 | AI27: 0 | AJ27: 0 | AK27: 0 | AL27: 0 | AM27: 0 | AN27: 0 | AO27: 0 | AP27: 0 | AQ27: 0 | AR27: 0 | AS27: 0 | AT27: 0 | AU27: 0 | AV27: 0 | AW27: 0 | AX27: 0
A28: PLTD SNYAN #5 | B28: 17.02 | C28: 0 | D28: 0 | E28: 0 | F28: 0 | G28: 0 | H28: 0 | I28: 0 | J28: 0 | K28: 0 | L28: 0 | M28: 0 | N28: 0 | O28: 0 | P28: 0 | Q28: 0 | R28: 0 | S28: 0 | T28: 0 | U28: 0 | V28: 0 | W28: 0 | X28: 0 | Y28: 0 | Z28: 0 | AA28: 0 | AB28: 0 | AC28: 0 | AD28: 0 | AE28: 0 | AF28: 0 | AG28: 0 | AH28: 0 | AI28: 0 | AJ28: 0 | AK28: 0 | AL28: 0 | AM28: 0 | AN28: 0 | AO28: 0 | AP28: 0 | AQ28: 0 | AR28: 0 | AS28: 0 | AT28: 0 | AU28: 0 | AV28: 0 | AW28: 0 | AX28: 0
A29: PLTD SNYAN #6 | B29: 17.02 | C29: 0 | D29: 0 | E29: 0 | F29: 0 | G29: 0 | H29: 0 | I29: 0 | J29: 0 | K29: 0 | L29: 0 | M29: 0 | N29: 0 | O29: 0 | P29: 0 | Q29: 0 | R29: 0 | S29: 0 | T29: 0 | U29: 0 | V29: 0 | W29: 0 | X29: 0 | Y29: 0 | Z29: 0 | AA29: 0 | AB29: 0 | AC29: 0 | AD29: 0 | AE29: 0 | AF29: 0 | AG29: 0 | AH29: 0 | AI29: 0 | AJ29: 0 | AK29: 0 | AL29: 0 | AM29: 0 | AN29: 0 | AO29: 0 | AP29: 0 | AQ29: 0 | AR29: 0 | AS29: 0 | AT29: 0 | AU29: 0 | AV29: 0 | AW29: 0 | AX29: 0
A31: PLTGU CLGN #1 | C31: 140.09 | D31: 140.09 | E31: 140.09 | F31: 140.09 | G31: 140.09 | H31: 140.09 | I31: 140.09 | J31: 140.09 | K31: 140.09 | L31: 140.09 | M31: 140.09 | N31: 140.09 | O31: 140.09 | P31: 140.09 | Q31: 140.09 | R31: 140.09 | S31: 140.09 | T31: 233.49 | U31: 233.49 | V31: 233.49 | W31: 233.49 | X31: 233.49 | Y31: 233.49 | Z31: 233.49 | AA31: 233.49 | AB31: 233.49 | AC31: 233.49 | AD31: 233.49 | AE31: 233.49 | AF31: 233.49 | AG31: 233.49 | AH31: 233.49 | AI31: 233.49 | AJ31: 233.49 | AK31: 233.49 | AL31: 233.49 | AM31: 233.49 | AN31: 233.49 | AO31: 233.49 | AP31: 233.49 | AQ31: 233.49 | AR31: 140.09 | AS31: 140.09 | AT31: 140.09 | AU31: 140.09 | AV31: 140.09 | AW31: 140.09 | AX31: 140.09
A33: PLTU LABUAN #1 | B33: 280 | C33: 250 | D33: 250 | E33: 250 | F33: 250 | G33: 250 | H33: 250 | I33: 250 | J33: 250 | K33: 250 | L33: 250 | M33: 250 | N33: 250 | O33: 250 | P33: 250 | Q33: 250 | R33: 250 | S33: 265 | T33: 265 | U33: 265 | V33: 265 | W33: 265 | X33: 265 | Y33: 265 | Z33: 265 | AA33: 265 | AB33: 265 | AC33: 265 | AD33: 265 | AE33: 265 | AF33: 265 | AG33: 265 | AH33: 265 | AI33: 265 | AJ33: 265 | AK33: 265 | AL33: 265 | AM33: 265 | AN33: 265 | AO33: 265 | AP33: 265 | AQ33: 265 | AR33: 265 | AS33: 265 | AT33: 265 | AU33: 250 | AV33: 250 | AW33: 250 | AX33: 250
A34: PLTU LABUAN #2 | B34: 280 | C34: 250 | D34: 250 | E34: 250 | F34: 250 | G34: 250 | H34: 250 | I34: 250 | J34: 250 | K34: 250 | L34: 250 | M34: 250 | N34: 250 | O34: 250 | P34: 250 | Q34: 250 | R34: 250 | S34: 270 | T34: 270 | U34: 270 | V34: 270 | W34: 270 | X34: 270 | Y34: 270 | Z34: 270 | AA34: 270 | AB34: 270 | AC34: 270 | AD34: 270 | AE34: 270 | AF34: 270 | AG34: 270 | AH34: 270 | AI34: 270 | AJ34: 270 | AK34: 270 | AL34: 270 | AM34: 270 | AN34: 270 | AO34: 270 | AP34: 270 | AQ34: 270 | AR34: 270 | AS34: 270 | AT34: 270 | AU34: 250 | AV34: 250 | AW34: 250 | AX34: 250
A36: PLTU SRLYA #8 | B36: 540 | C36: 405 | D36: 405 | E36: 405 | F36: 405 | G36: 405 | H36: 405 | I36: 405 | J36: 405 | K36: 405 | L36: 405 | M36: 405 | N36: 405 | O36: 405 | P36: 405 | Q36: 405 | R36: 405 | S36: 405 | T36: 405 | U36: 405 | V36: 405 | W36: 405 | X36: 405 | Y36: 405 | Z36: 405 | AA36: 405 | AB36: 405 | AC36: 405 | AD36: 405 | AE36: 405 | AF36: 405 | AG36: 405 | AH36: 405 | AI36: 405 | AJ36: 405 | AK36: 405 | AL36: 405 | AM36: 405 | AN36: 405 | AO36: 405 | AP36: 405 | AQ36: 405 | AR36: 405 | AS36: 405 | AT36: 405 | AU36: 405 | AV36: 405 | AW36: 405 | AX36: 405
A38: PLTU PRATU #1 | B38: 323 | C38: 260 | D38: 260 | E38: 260 | F38: 260 | G38: 260 | H38: 260 | I38: 260 | J38: 260 | K38: 260 | L38: 260 | M38: 260 | N38: 260 | O38: 260 | P38: 260 | Q38: 260 | R38: 260 | S38: 260 | T38: 265 | U38: 265 | V38: 265 | W38: 265 | X38: 265 | Y38: 265 | Z38: 265 | AA38: 265 | AB38: 265 | AC38: 265 | AD38: 265 | AE38: 265 | AF38: 265 | AG38: 265 | AH38: 265 | AI38: 265 | AJ38: 265 | AK38: 265 | AL38: 265 | AM38: 265 | AN38: 265 | AO38: 265 | AP38: 265 | AQ38: 265 | AR38: 265 | AS38: 265 | AT38: 265 | AU38: 265 | AV38: 265 | AW38: 265 | AX38: 265
A39: PLTU PRATU #2 | B39: 323 | C39: 260 | D39: 260 | E39: 260 | F39: 260 | G39: 260 | H39: 260 | I39: 260 | J39: 260 | K39: 260 | L39: 260 | M39: 260 | N39: 260 | O39: 260 | P39: 260 | Q39: 260 | R39: 260 | S39: 260 | T39: 265 | U39: 265 | V39: 265 | W39: 265 | X39: 265 | Y39: 265 | Z39: 265 | AA39: 265 | AB39: 265 | AC39: 265 | AD39: 265 | AE39: 265 | AF39: 265 | AG39: 265 | AH39: 265 | AI39: 265 | AJ39: 265 | AK39: 265 | AL39: 265 | AM39: 265 | AN39: 265 | AO39: 265 | AP39: 265 | AQ39: 265 | AR39: 265 | AS39: 265 | AT39: 265 | AU39: 265 | AV39: 265 | AW39: 265 | AX39: 265
A40: PLTU PRATU #3 | B40: 323 | C40: 260 | D40: 260 | E40: 260 | F40: 260 | G40: 260 | H40: 260 | I40: 260 | J40: 260 | K40: 260 | L40: 260 | M40: 260 | N40: 260 | O40: 260 | P40: 260 | Q40: 260 | R40: 260 | S40: 260 | T40: 265 | U40: 265 | V40: 265 | W40: 265 | X40: 265 | Y40: 265 | Z40: 265 | AA40: 265 | AB40: 265 | AC40: 265 | AD40: 265 | AE40: 265 | AF40: 265 | AG40: 265 | AH40: 265 | AI40: 265 | AJ40: 265 | AK40: 265 | AL40: 265 | AM40: 265 | AN40: 265 | AO40: 265 | AP40: 265 | AQ40: 265 | AR40: 265 | AS40: 265 | AT40: 265 | AU40: 265 | AV40: 265 | AW40: 265 | AX40: 265
A42: PLTU LONTAR #1 | B42: 280 | C42: 0 | D42: 0 | E42: 0 | F42: 0 | G42: 0 | H42: 0 | I42: 0 | J42: 0 | K42: 0 | L42: 0 | M42: 0 | N42: 0 | O42: 0 | P42: 0 | Q42: 0 | R42: 0 | S42: 0 | T42: 0 | U42: 0 | V42: 0 | W42: 0 | X42: 0 | Y42: 0 | Z42: 0 | AA42: 0 | AB42: 0 | AC42: 0 | AD42: 0 | AE42: 0 | AF42: 0 | AG42: 0 | AH42: 0 | AI42: 0 | AJ42: 0 | AK42: 0 | AL42: 0 | AM42: 0 | AN42: 0 | AO42: 0 | AP42: 0 | AQ42: 0 | AR42: 0 | AS42: 0 | AT42: 0 | AU42: 0 | AV42: 0 | AW42: 0 | AX42: 0
A43: PLTU LONTAR #2 | B43: 280 | C43: 250 | D43: 250 | E43: 250 | F43: 250 | G43: 250 | H43: 250 | I43: 250 | J43: 250 | K43: 250 | L43: 250 | M43: 250 | N43: 260 | O43: 260 | P43: 270 | Q43: 270 | R43: 270 | S43: 270 | T43: 270 | U43: 270 | V43: 270 | W43: 270 | X43: 270 | Y43: 270 | Z43: 270 | AA43: 270 | AB43: 270 | AC43: 270 | AD43: 270 | AE43: 270 | AF43: 270 | AG43: 270 | AH43: 270 | AI43: 270 | AJ43: 270 | AK43: 270 | AL43: 270 | AM43: 270 | AN43: 270 | AO43: 270 | AP43: 270 | AQ43: 270 | AR43: 275 | AS43: 275 | AT43: 250 | AU43: 250 | AV43: 250 | AW43: 250 | AX43: 250
A44: PLTU LONTAR #3 | B44: 280 | C44: 250 | D44: 250 | E44: 250 | F44: 250 | G44: 250 | H44: 250 | I44: 250 | J44: 250 | K44: 250 | L44: 250 | M44: 250 | N44: 260 | O44: 260 | P44: 270 | Q44: 270 | R44: 270 | S44: 270 | T44: 270 | U44: 270 | V44: 270 | W44: 270 | X44: 270 | Y44: 270 | Z44: 270 | AA44: 270 | AB44: 270 | AC44: 270 | AD44: 270 | AE44: 270 | AF44: 270 | AG44: 270 | AH44: 270 | AI44: 270 | AJ44: 270 | AK44: 270 | AL44: 270 | AM44: 270 | AN44: 270 | AO44: 270 | AP44: 270 | AQ44: 270 | AR44: 275 | AS44: 275 | AT44: 250 | AU44: 250 | AV44: 250 | AW44: 250 | AX44: 250
A45: PLTU LONTAR #4 | B45: 293 | C45: 200 | D45: 200 | E45: 200 | F45: 200 | G45: 200 | H45: 200 | I45: 200 | J45: 200 | K45: 200 | L45: 200 | M45: 200 | N45: 200 | O45: 200 | P45: 200 | Q45: 200 | R45: 220 | S45: 220 | T45: 220 | U45: 220 | V45: 220 | W45: 220 | X45: 220 | Y45: 220 | Z45: 220 | AA45: 220 | AB45: 220 | AC45: 220 | AD45: 220 | AE45: 220 | AF45: 220 | AG45: 220 | AH45: 220 | AI45: 220 | AJ45: 220 | AK45: 220 | AL45: 220 | AM45: 220 | AN45: 220 | AO45: 220 | AP45: 220 | AQ45: 220 | AR45: 200 | AS45: 200 | AT45: 200 | AU45: 200 | AV45: 200 | AW45: 200 | AX45: 200
A47: PLTU SRLYA #3 | B47: 371.5 | C47: 180 | D47: 180 | E47: 180 | F47: 180 | G47: 180 | H47: 180 | I47: 180 | J47: 180 | K47: 180 | L47: 180 | M47: 180 | N47: 180 | O47: 180 | P47: 180 | Q47: 180 | R47: 180 | S47: 180 | T47: 180 | U47: 180 | V47: 180 | W47: 180 | X47: 180 | Y47: 180 | Z47: 180 | AA47: 180 | AB47: 180 | AC47: 180 | AD47: 180 | AE47: 180 | AF47: 180 | AG47: 180 | AH47: 180 | AI47: 180 | AJ47: 180 | AK47: 180 | AL47: 180 | AM47: 180 | AN47: 180 | AO47: 180 | AP47: 180 | AQ47: 180 | AR47: 180 | AS47: 180 | AT47: 180 | AU47: 180 | AV47: 180 | AW47: 180 | AX47: 180
C48: PT. PEMBANGKITAN JAWA-BALI | D48: PT. PEMBANGKITAN JAWA-BALI | E48: PT. PEMBANGKITAN JAWA-BALI | F48: PT. PEMBANGKITAN JAWA-BALI | G48: PT. PEMBANGKITAN JAWA-BALI | H48: PT. PEMBANGKITAN JAWA-BALI | I48: PT. PEMBANGKITAN JAWA-BALI | J48: PT. PEMBANGKITAN JAWA-BALI | K48: PT. PEMBANGKITAN JAWA-BALI | L48: PT. PEMBANGKITAN JAWA-BALI | M48: PT. PEMBANGKITAN JAWA-BALI | N48: PT. PEMBANGKITAN JAWA-BALI | O48: PT. PEMBANGKITAN JAWA-BALI | P48: PT. PEMBANGKITAN JAWA-BALI | Q48: PT. PEMBANGKITAN JAWA-BALI | R48: PT. PEMBANGKITAN JAWA-BALI | S48: PT. PEMBANGKITAN JAWA-BALI | T48: PT. PEMBANGKITAN JAWA-BALI | U48: PT. PEMBANGKITAN JAWA-BALI | V48: PT. PEMBANGKITAN JAWA-BALI | W48: PT. PEMBANGKITAN JAWA-BALI | X48: PT. PEMBANGKITAN JAWA-BALI | Y48: PT. PEMBANGKITAN JAWA-BALI | Z48: PT. PEMBANGKITAN JAWA-BALI | AA48: PT. PEMBANGKITAN JAWA-BALI | AB48: PT. PEMBANGKITAN JAWA-BALI | AC48: PT. PEMBANGKITAN JAWA-BALI | AD48: PT. PEMBANGKITAN JAWA-BALI | AE48: PT. PEMBANGKITAN JAWA-BALI | AF48: PT. PEMBANGKITAN JAWA-BALI | AG48: PT. PEMBANGKITAN JAWA-BALI | AH48: PT. PEMBANGKITAN JAWA-BALI | AI48: PT. PEMBANGKITAN JAWA-BALI | AJ48: PT. PEMBANGKITAN JAWA-BALI | AK48: PT. PEMBANGKITAN JAWA-BALI | AL48: PT. PEMBANGKITAN JAWA-BALI | AM48: PT. PEMBANGKITAN JAWA-BALI | AN48: PT. PEMBANGKITAN JAWA-BALI | AO48: PT. PEMBANGKITAN JAWA-BALI | AP48: PT. PEMBANGKITAN JAWA-BALI | AQ48: PT. PEMBANGKITAN JAWA-BALI | AR48: PT. PEMBANGKITAN JAWA-BALI | AS48: PT. PEMBANGKITAN JAWA-BALI | AT48: PT. PEMBANGKITAN JAWA-BALI | AU48: PT. PEMBANGKITAN JAWA-BALI | AV48: PT. PEMBANGKITAN JAWA-BALI | AW48: PT. PEMBANGKITAN JAWA-BALI | AX48: PT. PEMBANGKITAN JAWA-BALI
A50: PLTU MKRNG #4 | B50: 162 | C50: 90 | D50: 90 | E50: 90 | F50: 90 | G50: 90 | H50: 90 | I50: 90 | J50: 90 | K50: 90 | L50: 90 | M50: 90 | N50: 90 | O50: 90 | P50: 90 | Q50: 90 | R50: 90 | S50: 90 | T50: 90 | U50: 90 | V50: 90 | W50: 90 | X50: 90 | Y50: 90 | Z50: 90 | AA50: 90 | AB50: 90 | AC50: 90 | AD50: 90 | AE50: 90 | AF50: 90 | AG50: 90 | AH50: 90 | AI50: 90 | AJ50: 90 | AK50: 90 | AL50: 90 | AM50: 90 | AN50: 90 | AO50: 90 | AP50: 90 | AQ50: 90 | AR50: 90 | AS50: 90 | AT50: 90 | AU50: 90 | AV50: 90 | AW50: 90 | AX50: 90
A51: PLTU MKRNG #5 | B51: 162 | C51: 0 | D51: 0 | E51: 0 | F51: 0 | G51: 0 | H51: 0 | I51: 0 | J51: 0 | K51: 0 | L51: 0 | M51: 0 | N51: 0 | O51: 0 | P51: 0 | Q51: 0 | R51: 0 | S51: 0 | T51: 0 | U51: 0 | V51: 0 | W51: 0 | X51: 0 | Y51: 0 | Z51: 0 | AA51: 0 | AB51: 0 | AC51: 0 | AD51: 0 | AE51: 0 | AF51: 0 | AG51: 0 | AH51: 0 | AI51: 0 | AJ51: 0 | AK51: 0 | AL51: 0 | AM51: 0 | AN51: 0 | AO51: 0 | AP51: 0 | AQ51: 0 | AR51: 0 | AS51: 0 | AT51: 0 | AU51: 0 | AV51: 0 | AW51: 0 | AX51: 0
A53: PLTGU MKRNG #1 | C53: 122.28 | D53: 122.28 | E53: 122.28 | F53: 122.28 | G53: 122.28 | H53: 122.28 | I53: 122.28 | J53: 122.28 | K53: 122.28 | L53: 122.28 | M53: 122.28 | N53: 122.28 | O53: 122.28 | P53: 122.28 | Q53: 151.25 | R53: 187.57 | S53: 187.57 | T53: 245.04 | U53: 281.36 | V53: 281.36 | W53: 281.36 | X53: 281.36 | Y53: 281.36 | Z53: 281.36 | AA53: 281.36 | AB53: 281.36 | AC53: 281.36 | AD53: 281.36 | AE53: 281.36 | AF53: 281.36 | AG53: 281.36 | AH53: 281.36 | AI53: 281.36 | AJ53: 281.36 | AK53: 281.36 | AL53: 331.86 | AM53: 306.52 | AN53: 281.36 | AO53: 281.36 | AP53: 270.72 | AQ53: 187.57 | AR53: 176.94 | AS53: 122.28 | AT53: 122.28 | AU53: 122.28 | AV53: 122.28 | AW53: 122.28 | AX53: 122.28
A54: PLTGU MKRNG #2 | C54: 180.85 | D54: 180.85 | E54: 180.85 | F54: 180.85 | G54: 210 | H54: 210 | I54: 210 | J54: 210 | K54: 210 | L54: 210 | M54: 210 | N54: 210 | O54: 180.85 | P54: 180.85 | Q54: 210 | R54: 180.85 | S54: 180.85 | T54: 180.85 | U54: 180.85 | V54: 183.18 | W54: 202.57 | X54: 227.05 | Y54: 220.1 | Z54: 185.52 | AA54: 180.85 | AB54: 201.89 | AC54: 255.49 | AD54: 273.91 | AE54: 328.29 | AF54: 328.29 | AG54: 335.98 | AH54: 251.74 | AI54: 180.85 | AJ54: 180.85 | AK54: 251.74 | AL54: 340 | AM54: 340 | AN54: 251.74 | AO54: 251.74 | AP54: 251.74 | AQ54: 251.74 | AR54: 251.74 | AS54: 251.74 | AT54: 251.74 | AU54: 251.74 | AV54: 234.69 | AW54: 211.35 | AX54: 250.54
...

Sheet ROH
A1: LOKASI | B1: DMN | C1: 00.30 | D1: 01.00 | E1: 01.30 | F1: 02.00 | G1: 02.30 | H1: 03.00 | I1: 03.30 | J1: 04.00 | K1: 04.30 | L1: 05.00 | M1: 05.30 | N1: 06.00 | O1: 06.30 | P1: 07.00 | Q1: 07.30 | R1: 08.00 | S1: 08.30 | T1: 09.00 | U1: 09.30 | V1: 10.00 | W1: 10.30 | X1: 11.00 | Y1: 11.30 | Z1: 12.00 | AA1: 12.30 | AB1: 13.00 | AC1: 13.30 | AD1: 14.00 | AE1: 14.30 | AF1: 15.00 | AG1: 15.30 | AH1: 16.00 | AI1: 16.30 | AJ1: 17.00 | AK1: 17.30 | AL1: 18.00 | AM1: 18.30 | AN1: 19.00 | AO1: 19.30 | AP1: 20.00 | AQ1: 20.30 | AR1: 21.00 | AS1: 21.30 | AT1: 22.00 | AU1: 22.30 | AV1: 23.00 | AW1: 23.30 | AX1: 24.00
A3: RJKB
C4: PT. INDONESIA POWER | D4: PT. INDONESIA POWER | E4: PT. INDONESIA POWER | F4: PT. INDONESIA POWER | G4: PT. INDONESIA POWER | H4: PT. INDONESIA POWER | I4: PT. INDONESIA POWER | J4: PT. INDONESIA POWER | K4: PT. INDONESIA POWER | L4: PT. INDONESIA POWER | M4: PT. INDONESIA POWER | N4: PT. INDONESIA POWER | O4: PT. INDONESIA POWER | P4: PT. INDONESIA POWER | Q4: PT. INDONESIA POWER | R4: PT. INDONESIA POWER | S4: PT. INDONESIA POWER | T4: PT. INDONESIA POWER | U4: PT. INDONESIA POWER | V4: PT. INDONESIA POWER | W4: PT. INDONESIA POWER | X4: PT. INDONESIA POWER | Y4: PT. INDONESIA POWER | Z4: PT. INDONESIA POWER | AA4: PT. INDONESIA POWER | AB4: PT. INDONESIA POWER | AC4: PT. INDONESIA POWER | AD4: PT. INDONESIA POWER | AE4: PT. INDONESIA POWER | AF4: PT. INDONESIA POWER | AG4: PT. INDONESIA POWER | AH4: PT. INDONESIA POWER | AI4: PT. INDONESIA POWER | AJ4: PT. INDONESIA POWER | AK4: PT. INDONESIA POWER | AL4: PT. INDONESIA POWER | AM4: PT. INDONESIA POWER | AN4: PT. INDONESIA POWER | AO4: PT. INDONESIA POWER | AP4: PT. INDONESIA POWER | AQ4: PT. INDONESIA POWER | AR4: PT. INDONESIA POWER | AS4: PT. INDONESIA POWER | AT4: PT. INDONESIA POWER | AU4: PT. INDONESIA POWER | AV4: PT. INDONESIA POWER | AW4: PT. INDONESIA POWER | AX4: PT. INDONESIA POWER
A6: PLTA Region 1 | C6: 4 | D6: 3 | E6: 3 | F6: 3 | G6: 3 | H6: 3 | I6: 3 | J6: 3 | K6: 3 | L6: 3 | M6: 3 | N6: 3 | O6: 4 | P6: 4 | Q6: 4 | R6: 4 | S6: 4 | T6: 4 | U6: 4 | V6: 4 | W6: 8 | X6: 8 | Y6: 8 | Z6: 8 | AA6: 8 | AB6: 8 | AC6: 8 | AD6: 8 | AE6: 8 | AF6: 8 | AG6: 8 | AH6: 8 | AI6: 8 | AJ6: 8 | AK6: 8 | AL6: 8 | AM6: 8 | AN6: 8 | AO6: 8 | AP6: 4 | AQ6: 4 | AR6: 4 | AS6: 4 | AT6: 4 | AU6: 4 | AV6: 4 | AW6: 4 | AX6: 4
A8: PLTU SRLYA #1 | B8: 371.5 | C8: 200 | D8: 200 | E8: 200 | F8: 200 | G8: 200 | H8: 200 | I8: 200 | J8: 200 | K8: 200 | L8: 200 | M8: 200 | N8: 200 | O8: 200 | P8: 200 | Q8: 200 | R8: 200 | S8: 200 | T8: 200 | U8: 200 | V8: 200 | W8: 200 | X8: 200 | Y8: 200 | Z8: 200 | AA8: 200 | AB8: 200 | AC8: 200 | AD8: 200 | AE8: 200 | AF8: 200 | AG8: 200 | AH8: 200 | AI8: 200 | AJ8: 200 | AK8: 200 | AL8: 200 | AM8: 200 | AN8: 200 | AO8: 200 | AP8: 200 | AQ8: 200 | AR8: 250.01 | AS8: 200 | AT8: 200 | AU8: 200 | AV8: 200 | AW8: 200 | AX8: 200
A9: PLTU SRLYA #2 | B9: 371.5 | C9: 200 | D9: 200 | E9: 200 | F9: 200 | G9: 200 | H9: 200 | I9: 200 | J9: 200 | K9: 200 | L9: 200 | M9: 200 | N9: 200 | O9: 200 | P9: 200 | Q9: 200 | R9: 200 | S9: 200 | T9: 240.51 | U9: 240.51 | V9: 240.51 | W9: 240.51 | X9: 240.51 | Y9: 240.51 | Z9: 240.51 | AA9: 240.51 | AB9: 240.51 | AC9: 240.51 | AD9: 240.51 | AE9: 240.51 | AF9: 240.51 | AG9: 240.51 | AH9: 240.51 | AI9: 240.51 | AJ9: 240.51 | AK9: 240.51 | AL9: 240.51 | AM9: 240.51 | AN9: 240.51 | AO9: 240.51 | AP9: 240.51 | AQ9: 240.51 | AR9: 284.2 | AS9: 200 | AT9: 200 | AU9: 200 | AV9: 200 | AW9: 200 | AX9: 200
A10: PLTU SRLYA #4 | B10: 371.5 | C10: 200 | D10: 200 | E10: 200 | F10: 200 | G10: 200 | H10: 200 | I10: 200 | J10: 200 | K10: 200 | L10: 200 | M10: 200 | N10: 200 | O10: 200 | P10: 200 | Q10: 200 | R10: 200 | S10: 200 | T10: 284.2 | U10: 284.2 | V10: 284.2 | W10: 284.2 | X10: 284.2 | Y10: 284.2 | Z10: 284.2 | AA10: 284.2 | AB10: 284.2 | AC10: 284.2 | AD10: 284.2 | AE10: 284.2 | AF10: 284.2 | AG10: 284.2 | AH10: 284.2 | AI10: 284.2 | AJ10: 284.2 | AK10: 284.2 | AL10: 284.2 | AM10: 284.2 | AN10: 284.2 | AO10: 284.2 | AP10: 284.2 | AQ10: 284.2 | AR10: 284.2 | AS10: 200 | AT10: 200 | AU10: 200 | AV10: 200 | AW10: 200 | AX10: 200
A11: PLTU SRLYA #5 | B11: 575.2 | C11: 500 | D11: 510 | E11: 510 | F11: 513.7 | G11: 563.7 | H11: 503.7 | I11: 503.7 | J11: 503.7 | K11: 503.7 | L11: 503.7 | M11: 503.7 | N11: 503.7 | O11: 563.7 | P11: 513.7 | Q11: 509.5 | R11: 419.5 | S11: 419.5 | T11: 563.7 | U11: 563.7 | V11: 563.7 | W11: 563.7 | X11: 563.7 | Y11: 563.7 | Z11: 563.7 | AA11: 563.7 | AB11: 563.7 | AC11: 563.7 | AD11: 563.7 | AE11: 563.7 | AF11: 563.7 | AG11: 563.7 | AH11: 563.7 | AI11: 563.7 | AJ11: 563.7 | AK11: 563.7 | AL11: 563.7 | AM11: 563.7 | AN11: 563.7 | AO11: 563.7 | AP11: 563.7 | AQ11: 563.7 | AR11: 563.7 | AS11: 490 | AT11: 513.7 | AU11: 563.7 | AV11: 503.7 | AW11: 503.7 | AX11: 503.7
A12: PLTU SRLYA #6 | B12: 575.2 | C12: 300 | D12: 300 | E12: 300 | F12: 300 | G12: 340 | H12: 490 | I12: 496.3 | J12: 496.3 | K12: 496.3 | L12: 496.3 | M12: 496.3 | N12: 490 | O12: 340 | P12: 300 | Q12: 300 | R12: 340 | S12: 340 | T12: 563.7 | U12: 563.7 | V12: 563.7 | W12: 563.7 | X12: 563.7 | Y12: 563.7 | Z12: 563.7 | AA12: 563.7 | AB12: 563.7 | AC12: 563.7 | AD12: 563.7 | AE12: 563.7 | AF12: 563.7 | AG12: 563.7 | AH12: 563.7 | AI12: 563.7 | AJ12: 563.7 | AK12: 563.7 | AL12: 563.7 | AM12: 563.7 | AN12: 563.7 | AO12: 563.7 | AP12: 563.7 | AQ12: 563.7 | AR12: 470 | AS12: 320 | AT12: 300 | AU12: 340 | AV12: 490 | AW12: 496.3 | AX12: 496.3
A13: PLTU SRLYA #7 | B13: 575.2 | C13: 500 | D13: 490 | E13: 490 | F13: 486.3 | G13: 396.3 | H13: 306.3 | I13: 300 | J13: 300 | K13: 300 | L13: 300 | M13: 300 | N13: 306.3 | O13: 396.3 | P13: 486.3 | Q13: 490.5 | R13: 540.5 | S13: 540.5 | T13: 563.7 | U13: 563.7 | V13: 563.7 | W13: 563.7 | X13: 563.7 | Y13: 563.7 | Z13: 563.7 | AA13: 563.7 | AB13: 563.7 | AC13: 563.7 | AD13: 563.7 | AE13: 563.7 | AF13: 563.7 | AG13: 563.7 | AH13: 563.7 | AI13: 563.7 | AJ13: 563.7 | AK13: 563.7 | AL13: 563.7 | AM13: 563.7 | AN13: 563.7 | AO13: 563.7 | AP13: 563.7 | AQ13: 563.7 | AR13: 563.7 | AS13: 490 | AT13: 486.3 | AU13: 396.3 | AV13: 306.3 | AW13: 300 | AX13: 300
A15: PLTGU PRIOK #1 | C15: 204.4 | D15: 204.4 | E15: 204.4 | F15: 204.4 | G15: 204.4 | H15: 204.4 | I15: 204.4 | J15: 204.4 | K15: 204.4 | L15: 204.4 | M15: 204.4 | N15: 279.55 | O15: 306.6 | P15: 547.5 | Q15: 547.5 | R15: 547.5 | S15: 547.5 | T15: 354.78 | U15: 355.67 | V15: 354.78 | W15: 354.78 | X15: 354.78 | Y15: 354.78 | Z15: 354.78 | AA15: 354.78 | AB15: 357.72 | AC15: 381.06 | AD15: 381.06 | AE15: 381.06 | AF15: 381.06 | AG15: 381.06 | AH15: 354.78 | AI15: 354.78 | AJ15: 354.78 | AK15: 354.78 | AL15: 386.9 | AM15: 354.78 | AN15: 354.78 | AO15: 354.78 | AP15: 354.78 | AQ15: 354.78 | AR15: 354.78 | AS15: 354.78 | AT15: 354.78 | AU15: 252.58 | AV15: 252.58 | AW15: 251.49 | AX15: 204.4
A16: PLTGU PRIOK #2 | C16: 204.4 | D16: 204.4 | E16: 204.4 | F16: 204.4 | G16: 204.4 | H16: 204.4 | I16: 204.4 | J16: 204.4 | K16: 204.4 | L16: 204.4 | M16: 204.4 | N16: 204.4 | O16: 204.4 | P16: 204.4 | Q16: 204.4 | R16: 204.4 | S16: 204.4 | T16: 252.58 | U16: 253.59 | V16: 252.58 | W16: 252.58 | X16: 252.58 | Y16: 252.58 | Z16: 252.58 | AA16: 252.58 | AB16: 261.31 | AC16: 278.86 | AD16: 278.86 | AE16: 278.86 | AF16: 278.86 | AG16: 278.86 | AH16: 252.58 | AI16: 252.58 | AJ16: 252.58 | AK16: 252.58 | AL16: 284.7 | AM16: 252.58 | AN16: 252.58 | AO16: 252.58 | AP16: 252.58 | AQ16: 252.58 | AR16: 252.58 | AS16: 252.58 | AT16: 252.58 | AU16: 252.58 | AV16: 231.54 | AW16: 250.23 | AX16: 248.21
A17: PLTGU PRIOK #3 | C17: 444.26 | D17: 444.26 | E17: 444.26 | F17: 444.26 | G17: 444.26 | H17: 444.26 | I17: 444.26 | J17: 444.26 | K17: 444.26 | L17: 444.26 | M17: 444.26 | N17: 444.26 | O17: 444.26 | P17: 444.26 | Q17: 444.26 | R17: 539.23 | S17: 539.23 | T17: 696.32 | U17: 720 | V17: 666.77 | W17: 697.07 | X17: 716.77 | Y17: 705.05 | Z17: 693.65 | AA17: 675.64 | AB17: 720 | AC17: 720 | AD17: 720 | AE17: 720 | AF17: 720 | AG17: 720 | AH17: 717.83 | AI17: 684.69 | AJ17: 652.11 | AK17: 582.64 | AL17: 720 | AM17: 713.87 | AN17: 626.55 | AO17: 582.24 | AP17: 539.23 | AQ17: 626.55 | AR17: 611.81 | AS17: 637.14 | AT17: 574.2 | AU17: 636.72 | AV17: 539.23 | AW17: 539.23 | AX17: 539.23
A18: PLTGU PRIOK #4 | C18: 0 | D18: 0 | E18: 0 | F18: 0 | G18: 0 | H18: 0 | I18: 0 | J18: 0 | K18: 0 | L18: 0 | M18: 0 | N18: 0 | O18: 0 | P18: 0 | Q18: 0 | R18: 0 | S18: 0 | T18: 0 | U18: 53.74 | V18: 150 | W18: 150 | X18: 150 | Y18: 150 | Z18: 150 | AA18: 150 | AB18: 150 | AC18: 164.97 | AD18: 172.28 | AE18: 179.16 | AF18: 180.01 | AG18: 168.78 | AH18: 150 | AI18: 150 | AJ18: 150 | AK18: 150 | AL18: 221 | AM18: 150 | AN18: 150 | AO18: 150 | AP18: 150 | AQ18: 75 | AR18: 25 | AS18: 0 | AT18: 0 | AU18: 0 | AV18: 0 | AW18: 0 | AX18: 0
A20: PLTP SALAK #1 | B20: 56.5 | C20: 56.5 | D20: 56.5 | E20: 56.5 | F20: 56.5 | G20: 56.5 | H20: 56.5 | I20: 56.5 | J20: 56.5 | K20: 56.5 | L20: 56.5 | M20: 56.5 | N20: 56.5 | O20: 56.5 | P20: 56.5 | Q20: 46.5 | R20: 46.5 | S20: 56.5 | T20: 56.5 | U20: 56.5 | V20: 56.5 | W20: 56.5 | X20: 56.5 | Y20: 56.5 | Z20: 56.5 | AA20: 56.5 | AB20: 56.5 | AC20: 56.5 | AD20: 56.5 | AE20: 56.5 | AF20: 56.5 | AG20: 56.5 | AH20: 56.5 | AI20: 56.5 | AJ20: 56.5 | AK20: 56.5 | AL20: 56.5 | AM20: 56.5 | AN20: 56.5 | AO20: 56.5 | AP20: 56.5 | AQ20: 56.5 | AR20: 56.5 | AS20: 56.5 | AT20: 56.5 | AU20: 56.5 | AV20: 56.5 | AW20: 56.5 | AX20: 56.5
A21: PLTP SALAK #2 | B21: 56.5 | C21: 56.5 | D21: 56.5 | E21: 56.5 | F21: 56.5 | G21: 56.5 | H21: 56.5 | I21: 56.5 | J21: 56.5 | K21: 56.5 | L21: 56.5 | M21: 56.5 | N21: 56.5 | O21: 56.5 | P21: 56.5 | Q21: 46.5 | R21: 46.5 | S21: 56.5 | T21: 56.5 | U21: 56.5 | V21: 56.5 | W21: 56.5 | X21: 56.5 | Y21: 56.5 | Z21: 56.5 | AA21: 56.5 | AB21: 56.5 | AC21: 56.5 | AD21: 56.5 | AE21: 56.5 | AF21: 56.5 | AG21: 56.5 | AH21: 56.5 | AI21: 56.5 | AJ21: 56.5 | AK21: 56.5 | AL21: 56.5 | AM21: 56.5 | AN21: 56.5 | AO21: 56.5 | AP21: 56.5 | AQ21: 56.5 | AR21: 56.5 | AS21: 56.5 | AT21: 56.5 | AU21: 56.5 | AV21: 56.5 | AW21: 56.5 | AX21: 56.5
A22: PLTP SALAK #3 | B22: 57 | C22: 57 | D22: 57 | E22: 57 | F22: 57 | G22: 57 | H22: 57 | I22: 57 | J22: 57 | K22: 57 | L22: 57 | M22: 57 | N22: 57 | O22: 57 | P22: 57 | Q22: 47 | R22: 47 | S22: 57 | T22: 57 | U22: 57 | V22: 57 | W22: 57 | X22: 57 | Y22: 57 | Z22: 57 | AA22: 57 | AB22: 57 | AC22: 57 | AD22: 57 | AE22: 57 | AF22: 57 | AG22: 57 | AH22: 57 | AI22: 57 | AJ22: 57 | AK22: 57 | AL22: 57 | AM22: 57 | AN22: 57 | AO22: 57 | AP22: 57 | AQ22: 57 | AR22: 57 | AS22: 57 | AT22: 57 | AU22: 57 | AV22: 57 | AW22: 57 | AX22: 57
A24: PLTD SNYAN #1 | B24: 17.02 | C24: 0 | D24: 0 | E24: 0 | F24: 0 | G24: 0 | H24: 0 | I24: 0 | J24: 0 | K24: 0 | L24: 0 | M24: 0 | N24: 0 | O24: 0 | P24: 0 | Q24: 0 | R24: 0 | S24: 0 | T24: 0 | U24: 0 | V24: 0 | W24: 0 | X24: 0 | Y24: 0 | Z24: 0 | AA24: 0 | AB24: 0 | AC24: 0 | AD24: 0 | AE24: 0 | AF24: 0 | AG24: 0 | AH24: 0 | AI24: 0 | AJ24: 0 | AK24: 0 | AL24: 0 | AM24: 0 | AN24: 0 | AO24: 0 | AP24: 0 | AQ24: 0 | AR24: 0 | AS24: 0 | AT24: 0 | AU24: 0 | AV24: 0 | AW24: 0 | AX24: 0
A25: PLTD SNYAN #2 | B25: 17.02 | C25: 0 | D25: 0 | E25: 0 | F25: 0 | G25: 0 | H25: 0 | I25: 0 | J25: 0 | K25: 0 | L25: 0 | M25: 0 | N25: 0 | O25: 0 | P25: 0 | Q25: 0 | R25: 0 | S25: 0 | T25: 0 | U25: 0 | V25: 0 | W25: 0 | X25: 0 | Y25: 0 | Z25: 0 | AA25: 0 | AB25: 0 | AC25: 0 | AD25: 0 | AE25: 0 | AF25: 0 | AG25: 0 | AH25: 0 | AI25: 0 | AJ25: 0 | AK25: 0 | AL25: 0 | AM25: 0 | AN25: 0 | AO25: 0 | AP25: 0 | AQ25: 0 | AR25: 0 | AS25: 0 | AT25: 0 | AU25: 0 | AV25: 0 | AW25: 0 | AX25: 0
A26: PLTD SNYAN #3 | B26: 17.02 | C26: 0 | D26: 0 | E26: 0 | F26: 0 | G26: 0 | H26: 0 | I26: 0 | J26: 0 | K26: 0 | L26: 0 | M26: 0 | N26: 0 | O26: 0 | P26: 0 | Q26: 0 | R26: 0 | S26: 0 | T26: 0 | U26: 0 | V26: 0 | W26: 0 | X26: 0 | Y26: 0 | Z26: 0 | AA26: 0 | AB26: 0 | AC26: 0 | AD26: 0 | AE26: 0 | AF26: 0 | AG26: 0 | AH26: 0 | AI26: 0 | AJ26: 0 | AK26: 0 | AL26: 0 | AM26: 0 | AN26: 0 | AO26: 0 | AP26: 0 | AQ26: 0 | AR26: 0 | AS26: 0 | AT26: 0 | AU26: 0 | AV26: 0 | AW26: 0 | AX26: 0
A27: PLTD SNYAN #4 | B27: 17.02 | C27: 0 | D27: 0 | E27: 0 | F27: 0 | G27: 0 | H27: 0 | I27: 0 | J27: 0 | K27: 0 | L27: 0 | M27: 0 | N27: 0 | O27: 0 | P27: 0 | Q27: 0 | R27: 0 | S27: 0 | T27: 0 | U27: 0 | V27: 0 | W27: 0 | X27: 0 | Y27: 0 | Z27: 0 | AA27: 0 | AB27: 0 | AC27: 0 | AD27: 0 | AE27: 0 | AF27: 0 | AG27: 0 | AH27: 0 | AI27: 0 | AJ27: 0 | AK27: 0 | AL27: 0 | AM27: 0 | AN27: 0 | AO27: 0 | AP27: 0 | AQ27: 0 | AR27: 0 | AS27: 0 | AT27: 0 | AU27: 0 | AV27: 0 | AW27: 0 | AX27: 0
A28: PLTD SNYAN #5 | B28: 17.02 | C28: 0 | D28: 0 | E28: 0 | F28: 0 | G28: 0 | H28: 0 | I28: 0 | J28: 0 | K28: 0 | L28: 0 | M28: 0 | N28: 0 | O28: 0 | P28: 0 | Q28: 0 | R28: 0 | S28: 0 | T28: 0 | U28: 0 | V28: 0 | W28: 0 | X28: 0 | Y28: 0 | Z28: 0 | AA28: 0 | AB28: 0 | AC28: 0 | AD28: 0 | AE28: 0 | AF28: 0 | AG28: 0 | AH28: 0 | AI28: 0 | AJ28: 0 | AK28: 0 | AL28: 0 | AM28: 0 | AN28: 0 | AO28: 0 | AP28: 0 | AQ28: 0 | AR28: 0 | AS28: 0 | AT28: 0 | AU28: 0 | AV28: 0 | AW28: 0 | AX28: 0
A29: PLTD SNYAN #6 | B29: 17.02 | C29: 0 | D29: 0 | E29: 0 | F29: 0 | G29: 0 | H29: 0 | I29: 0 | J29: 0 | K29: 0 | L29: 0 | M29: 0 | N29: 0 | O29: 0 | P29: 0 | Q29: 0 | R29: 0 | S29: 0 | T29: 0 | U29: 0 | V29: 0 | W29: 0 | X29: 0 | Y29: 0 | Z29: 0 | AA29: 0 | AB29: 0 | AC29: 0 | AD29: 0 | AE29: 0 | AF29: 0 | AG29: 0 | AH29: 0 | AI29: 0 | AJ29: 0 | AK29: 0 | AL29: 0 | AM29: 0 | AN29: 0 | AO29: 0 | AP29: 0 | AQ29: 0 | AR29: 0 | AS29: 0 | AT29: 0 | AU29: 0 | AV29: 0 | AW29: 0 | AX29: 0
A31: PLTGU CLGN #1 | C31: 140.09 | D31: 140.09 | E31: 140.09 | F31: 140.09 | G31: 140.09 | H31: 140.09 | I31: 140.09 | J31: 140.09 | K31: 140.09 | L31: 140.09 | M31: 140.09 | N31: 140.09 | O31: 140.09 | P31: 140.09 | Q31: 140.09 | R31: 140.09 | S31: 140.09 | T31: 233.49 | U31: 233.49 | V31: 233.49 | W31: 233.49 | X31: 233.49 | Y31: 233.49 | Z31: 233.49 | AA31: 233.49 | AB31: 233.49 | AC31: 233.49 | AD31: 233.49 | AE31: 233.49 | AF31: 233.49 | AG31: 233.49 | AH31: 233.49 | AI31: 233.49 | AJ31: 233.49 | AK31: 233.49 | AL31: 233.49 | AM31: 233.49 | AN31: 233.49 | AO31: 233.49 | AP31: 233.49 | AQ31: 233.49 | AR31: 140.09 | AS31: 140.09 | AT31: 140.09 | AU31: 140.09 | AV31: 140.09 | AW31: 140.09 | AX31: 140.09
A33: PLTU LABUAN #1 | B33: 280 | C33: 240 | D33: 240 | E33: 240 | F33: 240 | G33: 240 | H33: 240 | I33: 240 | J33: 240 | K33: 240 | L33: 240 | M33: 240 | N33: 240 | O33: 240 | P33: 240 | Q33: 240 | R33: 240 | S33: 240 | T33: 240 | U33: 240 | V33: 240 | W33: 240 | X33: 240 | Y33: 240 | Z33: 240 | AA33: 240 | AB33: 260 | AC33: 260 | AD33: 260 | AE33: 260 | AF33: 260 | AG33: 260 | AH33: 260 | AI33: 260 | AJ33: 260 | AK33: 260 | AL33: 260 | AM33: 260 | AN33: 260 | AO33: 260 | AP33: 260 | AQ33: 260 | AR33: 260 | AS33: 260 | AT33: 260 | AU33: 240 | AV33: 240 | AW33: 240 | AX33: 240
A34: PLTU LABUAN #2 | B34: 280 | C34: 240 | D34: 240 | E34: 240 | F34: 240 | G34: 240 | H34: 240 | I34: 240 | J34: 240 | K34: 240 | L34: 240 | M34: 240 | N34: 240 | O34: 240 | P34: 240 | Q34: 240 | R34: 240 | S34: 240 | T34: 240 | U34: 240 | V34: 240 | W34: 240 | X34: 240 | Y34: 240 | Z34: 240 | AA34: 240 | AB34: 260 | AC34: 260 | AD34: 260 | AE34: 260 | AF34: 260 | AG34: 260 | AH34: 260 | AI34: 260 | AJ34: 260 | AK34: 260 | AL34: 260 | AM34: 260 | AN34: 260 | AO34: 260 | AP34: 260 | AQ34: 260 | AR34: 260 | AS34: 260 | AT34: 260 | AU34: 240 | AV34: 240 | AW34: 240 | AX34: 240
A36: PLTU SRLYA #8 | B36: 540 | C36: 400 | D36: 400 | E36: 400 | F36: 400 | G36: 400 | H36: 400 | I36: 400 | J36: 400 | K36: 400 | L36: 400 | M36: 400 | N36: 400 | O36: 400 | P36: 400 | Q36: 400 | R36: 400 | S36: 400 | T36: 400 | U36: 400 | V36: 400 | W36: 400 | X36: 400 | Y36: 400 | Z36: 400 | AA36: 400 | AB36: 400 | AC36: 400 | AD36: 400 | AE36: 400 | AF36: 400 | AG36: 400 | AH36: 400 | AI36: 400 | AJ36: 400 | AK36: 400 | AL36: 400 | AM36: 400 | AN36: 400 | AO36: 400 | AP36: 400 | AQ36: 400 | AR36: 400 | AS36: 400 | AT36: 400 | AU36: 400 | AV36: 400 | AW36: 400 | AX36: 400
A38: PLTU PRATU #1 | B38: 323 | C38: 300 | D38: 300 | E38: 300 | F38: 300 | G38: 300 | H38: 300 | I38: 300 | J38: 300 | K38: 300 | L38: 300 | M38: 300 | N38: 300 | O38: 300 | P38: 300 | Q38: 300 | R38: 300 | S38: 300 | T38: 310 | U38: 310 | V38: 310 | W38: 310 | X38: 310 | Y38: 310 | Z38: 310 | AA38: 310 | AB38: 310 | AC38: 310 | AD38: 310 | AE38: 310 | AF38: 310 | AG38: 310 | AH38: 310 | AI38: 310 | AJ38: 315 | AK38: 315 | AL38: 315 | AM38: 315 | AN38: 315 | AO38: 315 | AP38: 315 | AQ38: 315 | AR38: 315 | AS38: 315 | AT38: 315 | AU38: 315 | AV38: 300 | AW38: 300 | AX38: 300
A39: PLTU PRATU #2 | B39: 323 | C39: 300 | D39: 300 | E39: 300 | F39: 300 | G39: 300 | H39: 300 | I39: 300 | J39: 300 | K39: 300 | L39: 300 | M39: 300 | N39: 300 | O39: 300 | P39: 300 | Q39: 300 | R39: 300 | S39: 300 | T39: 310 | U39: 310 | V39: 310 | W39: 310 | X39: 310 | Y39: 310 | Z39: 310 | AA39: 310 | AB39: 310 | AC39: 310 | AD39: 310 | AE39: 310 | AF39: 310 | AG39: 310 | AH39: 310 | AI39: 310 | AJ39: 315 | AK39: 315 | AL39: 315 | AM39: 315 | AN39: 315 | AO39: 315 | AP39: 315 | AQ39: 315 | AR39: 315 | AS39: 315 | AT39: 315 | AU39: 315 | AV39: 300 | AW39: 300 | AX39: 300
A40: PLTU PRATU #3 | B40: 323 | C40: 135 | D40: 135 | E40: 135 | F40: 135 | G40: 135 | H40: 135 | I40: 135 | J40: 135 | K40: 135 | L40: 135 | M40: 135 | N40: 135 | O40: 135 | P40: 135 | Q40: 135 | R40: 135 | S40: 135 | T40: 135 | U40: 135 | V40: 135 | W40: 135 | X40: 135 | Y40: 135 | Z40: 135 | AA40: 135 | AB40: 135 | AC40: 135 | AD40: 135 | AE40: 135 | AF40: 135 | AG40: 135 | AH40: 135 | AI40: 135 | AJ40: 135 | AK40: 135 | AL40: 135 | AM40: 135 | AN40: 135 | AO40: 135 | AP40: 135 | AQ40: 135 | AR40: 135 | AS40: 135 | AT40: 135 | AU40: 135 | AV40: 135 | AW40: 135 | AX40: 135
A42: PLTU LONTAR #1 | B42: 280 | C42: 0 | D42: 0 | E42: 0 | F42: 0 | G42: 0 | H42: 0 | I42: 0 | J42: 0 | K42: 0 | L42: 0 | M42: 0 | N42: 0 | O42: 0 | P42: 0 | Q42: 0 | R42: 0 | S42: 0 | T42: 0 | U42: 0 | V42: 0 | W42: 0 | X42: 0 | Y42: 0 | Z42: 0 | AA42: 0 | AB42: 0 | AC42: 0 | AD42: 0 | AE42: 0 | AF42: 0 | AG42: 0 | AH42: 0 | AI42: 0 | AJ42: 0 | AK42: 0 | AL42: 0 | AM42: 0 | AN42: 0 | AO42: 0 | AP42: 0 | AQ42: 0 | AR42: 0 | AS42: 0 | AT42: 0 | AU42: 0 | AV42: 0 | AW42: 0 | AX42: 0
A43: PLTU LONTAR #2 | B43: 280 | C43: 250 | D43: 250 | E43: 250 | F43: 250 | G43: 250 | H43: 250 | I43: 250 | J43: 250 | K43: 250 | L43: 250 | M43: 250 | N43: 260 | O43: 260 | P43: 275 | Q43: 275 | R43: 280 | S43: 280 | T43: 280 | U43: 280 | V43: 280 | W43: 280 | X43: 280 | Y43: 280 | Z43: 280 | AA43: 280 | AB43: 280 | AC43: 280 | AD43: 280 | AE43: 280 | AF43: 280 | AG43: 280 | AH43: 280 | AI43: 280 | AJ43: 280 | AK43: 280 | AL43: 280 | AM43: 280 | AN43: 280 | AO43: 280 | AP43: 280 | AQ43: 280 | AR43: 275 | AS43: 275 | AT43: 250 | AU43: 250 | AV43: 250 | AW43: 250 | AX43: 250
A44: PLTU LONTAR #3 | B44: 280 | C44: 250 | D44: 250 | E44: 250 | F44: 250 | G44: 250 | H44: 250 | I44: 250 | J44: 250 | K44: 250 | L44: 250 | M44: 250 | N44: 260 | O44: 260 | P44: 275 | Q44: 275 | R44: 280 | S44: 280 | T44: 280 | U44: 280 | V44: 280 | W44: 280 | X44: 280 | Y44: 280 | Z44: 280 | AA44: 280 | AB44: 280 | AC44: 280 | AD44: 280 | AE44: 280 | AF44: 280 | AG44: 280 | AH44: 280 | AI44: 280 | AJ44: 280 | AK44: 280 | AL44: 280 | AM44: 280 | AN44: 280 | AO44: 280 | AP44: 280 | AQ44: 280 | AR44: 275 | AS44: 275 | AT44: 250 | AU44: 250 | AV44: 250 | AW44: 250 | AX44: 250
A45: PLTU LONTAR #4 | B45: 293 | C45: 220 | D45: 220 | E45: 220 | F45: 220 | G45: 220 | H45: 220 | I45: 220 | J45: 220 | K45: 220 | L45: 220 | M45: 220 | N45: 220 | O45: 220 | P45: 220 | Q45: 220 | R45: 240 | S45: 240 | T45: 240 | U45: 240 | V45: 240 | W45: 240 | X45: 240 | Y45: 240 | Z45: 240 | AA45: 240 | AB45: 240 | AC45: 240 | AD45: 240 | AE45: 240 | AF45: 240 | AG45: 240 | AH45: 240 | AI45: 240 | AJ45: 240 | AK45: 240 | AL45: 240 | AM45: 240 | AN45: 240 | AO45: 240 | AP45: 240 | AQ45: 240 | AR45: 220 | AS45: 220 | AT45: 220 | AU45: 220 | AV45: 220 | AW45: 220 | AX45: 220
A47: PLTU SRLYA #3 | B47: 371.5 | C47: 200 | D47: 200 | E47: 200 | F47: 200 | G47: 200 | H47: 200 | I47: 200 | J47: 200 | K47: 200 | L47: 200 | M47: 200 | N47: 200 | O47: 200 | P47: 200 | Q47: 200 | R47: 200 | S47: 200 | T47: 284.2 | U47: 284.2 | V47: 284.2 | W47: 284.2 | X47: 284.2 | Y47: 284.2 | Z47: 284.2 | AA47: 284.2 | AB47: 284.2 | AC47: 284.2 | AD47: 284.2 | AE47: 284.2 | AF47: 284.2 | AG47: 284.2 | AH47: 284.2 | AI47: 284.2 | AJ47: 284.2 | AK47: 284.2 | AL47: 284.2 | AM47: 284.2 | AN47: 284.2 | AO47: 284.2 | AP47: 284.2 | AQ47: 284.2 | AR47: 284.2 | AS47: 200 | AT47: 200 | AU47: 200 | AV47: 200 | AW47: 200 | AX47: 200
